Workbook

Sheet CASE MASTER
A1: Study Code | B1: Sample Status (s/i) | C1: Sample Type | D1: Date of Collection | E1: Time of Collection | F1: Freeze Date | G1: Freeze Time | H1: CDI Location | I1: NIH Location | J1: MAX Planck Location | K1: WB Location | L1: Cryovial Tubes (Yes/No) | M1: Cryovial Location | N1: Cryovial Volumes | O1: Additional Notes (If any) | P1: Participant Helper | Q1: DateCode Helper | R1: Matrix Code Helper | S1: WB Code Helper | T1: Cryo Box Helper | U1: Cryo Start Row 1 | V1: Cryo Start Col 1 | W1: Cryo End Row 1 | X1: Cryo End Col 1 | Y1: Cryo Prefix Helper | Z1: Cryo Count 1 | AA1: Cryo Start Row 2 | AB1: Cryo Start Col 2 | AC1: Cryo End Row 2 | AD1: Cryo End Col 2 | AE1: Cryo Count 2
F2: =IF(AND($A2<>"",$B2<>"",$C2<>"",$D2<>"",$E2<>""),TODAY(),"") | H2: =IF(AND($A2<>"",$B2<>"",$C2<>"",$D2<>"",$E2<>""),IF(AND($B2="s",OR($C2="SER",$C2="PLH",$C2="CSF")),"Case CDI Plate "&(INT(((COUNTIFS($B$2:$B2,"s",$C$2:$C2,"SER")+COUNTIFS($B$2:$B2,"s",$C$2:$C2,"PLH")+COUNTIFS($B$2:$B2,"s",$C$2:$C2,"CSF"))-1)/96)+1)&": "&CHAR(65+INT(MOD((COUNTIFS($B$2:$B2,"s",$C$2:$C2,"SER")+COUNTIFS($B$2:$B2,"s",$C$2:$C2,"PLH")+COUNTIFS($B$2:$B2,"s",$C$2:$C2,"CSF"))-1,96)/12))&(MOD((COUNTIFS($B$2:$B2,"s",$C$2:$C2,"SER")+COUNTIFS($B$2:$B2,"s",$C$2:$C2,"PLH")+COUNTIFS($B$2:$B2,"s",$C$2:$C2,"CSF"))-1,12)+1),"N/A"),"") | I2: =IF(AND($A2<>"",$B2<>"",$C2<>"",$D2<>"",$E2<>""),IF(AND($B2="s",OR($C2="SER",$C2="PLH",$C2="CSF")),"Case NIH Plate "&(INT(((COUNTIFS($B$2:$B2,"s",$C$2:$C2,"SER")+COUNTIFS($B$2:$B2,"s",$C$2:$C2,"PLH")+COUNTIFS($B$2:$B2,"s",$C$2:$C2,"CSF"))-1)/96)+1)&": "&CHAR(65+INT(MOD((COUNTIFS($B$2:$B2,"s",$C$2:$C2,"SER")+COUNTIFS($B$2:$B2,"s",$C$2:$C2,"PLH")+COUNTIFS($B$2:$B2,"s",$C$2:$C2,"CSF"))-1,96)/12))&(MOD((COUNTIFS($B$2:$B2,"s",$C$2:$C2,"SER")+COUNTIFS($B$2:$B2,"s",$C$2:$C2,"PLH")+COUNTIFS($B$2:$B2,"s",$C$2:$C2,"CSF"))-1,12)+1),"N/A"),"") | J2: =IF(AND($A2<>"",$B2<>"",$C2<>"",$D2<>"",$E2<>""),IF(AND($B2="s",OR($C2="SER",$C2="PLH")),"Case MAX Planck Plate "&(INT(((COUNTIFS($B$2:$B2,"s",$C$2:$C2,"SER")+COUNTIFS($B$2:$B2,"s",$C$2:$C2,"PLH"))-1)/96)+1)&": "&CHAR(65+INT(MOD((COUNTIFS($B$2:$B2,"s",$C$2:$C2,"SER")+COUNTIFS($B$2:$B2,"s",$C$2:$C2,"PLH"))-1,96)/12))&(MOD((COUNTIFS($B$2:$B2,"s",$C$2:$C2,"SER")+COUNTIFS($B$2:$B2,"s",$C$2:$C2,"PLH"))-1,12)+1),"N/A"),"") | K2: =IF(AND($A2<>"",$B2<>"",$C2<>"",$D2<>"",$E2<>""),IF($C2="WB","Case WB Box "&(INT((COUNTIFS($C$2:$C2,"WB")-1)/81)+1)&": "&CHAR(65+INT(MOD(COUNTIFS($C$2:$C2,"WB")-1,81)/9))&(MOD(COUNTIFS($C$2:$C2,"WB")-1,9)+1),"N/A"),"") | L2: =IF(AND($A2<>"",$B2<>"",$C2<>"",$D2<>"",$E2<>""),IF($C2="WB","No",IF($B2="i","Yes","")),"") | P2: =IF($A2<>"",MID($A2,5,4),"") | Q2: =IF($D2<>"",TEXT($D2,"mmddyy"),"") | R2: =IF(AND($A2<>"",$B2<>"",$C2<>"",$D2<>""),IF($C2="WB","cs_"&$P2&"_"&$B2&"_wb_"&$Q2,"cs_"&$P2&"_"&$B2&"_"&LOWER($C2)&"_"&IF($C2="CSF","0.50","0.20")&"_"&$Q2),"") | S2: =IF(AND($A2<>"",$B2<>"",$C2="WB",$D2<>""),"cs_"&$P2&"_"&$B2&"_wb_"&$Q2,"") | T2: =IFERROR(VALUE(MID($M2,FIND("Box ",$M2)+4,FIND(":",$M2)-FIND("Box ",$M2)-4)),"") | U2: =IFERROR(CODE(UPPER(LEFT(LEFT(TRIM(MID(SUBSTITUTE(TRIM(MID($M2,FIND(":",$M2)+1,200)),",",REPT(" ",60)),1,60)),IFERROR(FIND("-",TRIM(MID(SUBSTITUTE(TRIM(MID($M2,FIND(":",$M2)+1,200)),",",REPT(" ",60)),1,60)))-1,LEN(TRIM(MID(SUBSTITUTE(TRIM(MID($M2,FIND(":",$M2)+1,200)),",",REPT(" ",60)),1,60))))),1)))-64,"") | V2: =IFERROR(VALUE(MID(LEFT(TRIM(MID(SUBSTITUTE(TRIM(MID($M2,FIND(":",$M2)+1,200)),",",REPT(" ",60)),1,60)),IFERROR(FIND("-",TRIM(MID(SUBSTITUTE(TRIM(MID($M2,FIND(":",$M2)+1,200)),",",REPT(" ",60)),1,60)))-1,LEN(TRIM(MID(SUBSTITUTE(TRIM(MID($M2,FIND(":",$M2)+1,200)),",",REPT(" ",60)),1,60))))),2,3)),"") | W2: =IFERROR(CODE(UPPER(LEFT(IFERROR(MID(TRIM(MID(SUBSTITUTE(TRIM(MID($M2,FIND(":",$M2)+1,200)),",",REPT(" ",60)),1,60)),FIND("-",TRIM(MID(SUBSTITUTE(TRIM(MID($M2,FIND(":",$M2)+1,200)),",",REPT(" ",60)),1,60)))+1,99),LEFT(TRIM(MID(SUBSTITUTE(TRIM(MID($M2,FIND(":",$M2)+1,200)),",",REPT(" ",60)),1,60)),IFERROR(FIND("-",TRIM(MID(SUBSTITUTE(TRIM(MID($M2,FIND(":",$M2)+1,200)),",",REPT(" ",60)),1,60)))-1,LEN(TRIM(MID(SUBSTITUTE(TRIM(MID($M2,FIND(":",$M2)+1,200)),",",REPT(" ",60)),1,60)))))),1)))-64,"") | X2: =IFERROR(VALUE(MID(IFERROR(MID(TRIM(MID(SUBSTITUTE(TRIM(MID($M2,FIND(":",$M2)+1,200)),",",REPT(" ",60)),1,60)),FIND("-",TRIM(MID(SUBSTITUTE(TRIM(MID($M2,FIND(":",$M2)+1,200)),",",REPT(" ",60)),1,60)))+1,99),LEFT(TRIM(MID(SUBSTITUTE(TRIM(MID($M2,FIND(":",$M2)+1,200)),",",REPT(" ",60)),1,60)),IFERROR(FIND("-",TRIM(MID(SUBSTITUTE(TRIM(MID($M2,FIND(":",$M2)+1,200)),",",REPT(" ",60)),1,60)))-1,LEN(TRIM(MID(SUBSTITUTE(TRIM(MID($M2,FIND(":",$M2)+1,200)),",",REPT(" ",60)),1,60)))))),2,3)),"") | Y2: =IF(AND($A2<>"",$B2<>"",$C2<>"",$D2<>""),"cs_"&$P2&"_"&$B2&"_"&LOWER($C2)&"_","") | Z2: =IFERROR(($W2-$U2+1)*($X2-$V2+1),0) -> 0 | AA2: =IFERROR(CODE(UPPER(LEFT(LEFT(TRIM(MID(SUBSTITUTE(TRIM(MID($M2,FIND(":",$M2)+1,200)),",",REPT(" ",60)),61,60)),IFERROR(FIND("-",TRIM(MID(SUBSTITUTE(TRIM(MID($M2,FIND(":",$M2)+1,200)),",",REPT(" ",60)),61,60)))-1,LEN(TRIM(MID(SUBSTITUTE(TRIM(MID($M2,FIND(":",$M2)+1,200)),",",REPT(" ",60)),61,60))))),1)))-64,"") | AB2: =IFERROR(VALUE(MID(LEFT(TRIM(MID(SUBSTITUTE(TRIM(MID($M2,FIND(":",$M2)+1,200)),",",REPT(" ",60)),61,60)),IFERROR(FIND("-",TRIM(MID(SUBSTITUTE(TRIM(MID($M2,FIND(":",$M2)+1,200)),",",REPT(" ",60)),61,60)))-1,LEN(TRIM(MID(SUBSTITUTE(TRIM(MID($M2,FIND(":",$M2)+1,200)),",",REPT(" ",60)),61,60))))),2,3)),"") | AC2: =IFERROR(CODE(UPPER(LEFT(IFERROR(MID(TRIM(MID(SUBSTITUTE(TRIM(MID($M2,FIND(":",$M2)+1,200)),",",REPT(" ",60)),61,60)),FIND("-",TRIM(MID(SUBSTITUTE(TRIM(MID($M2,FIND(":",$M2)+1,200)),",",REPT(" ",60)),61,60)))+1,99),LEFT(TRIM(MID(SUBSTITUTE(TRIM(MID($M2,FIND(":",$M2)+1,200)),",",REPT(" ",60)),61,60)),IFERROR(FIND("-",TRIM(MID(SUBSTITUTE(TRIM(MID($M2,FIND(":",$M2)+1,200)),",",REPT(" ",60)),61,60)))-1,LEN(TRIM(MID(SUBSTITUTE(TRIM(MID($M2,FIND(":",$M2)+1,200)),",",REPT(" ",60)),61,60)))))),1)))-64,"") | AD2: =IFERROR(VALUE(MID(IFERROR(MID(TRIM(MID(SUBSTITUTE(TRIM(MID($M2,FIND(":",$M2)+1,200)),",",REPT(" ",60)),61,60)),FIND("-",TRIM(MID(SUBSTITUTE(TRIM(MID($M2,FIND(":",$M2)+1,200)),",",REPT(" ",60)),61,60)))+1,99),LEFT(TRIM(MID(SUBSTITUTE(TRIM(MID($M2,FIND(":",$M2)+1,200)),",",REPT(" ",60)),61,60)),IFERROR(FIND("-",TRIM(MID(SUBSTITUTE(TRIM(MID($M2,FIND(":",$M2)+1,200)),",",REPT(" ",60)),61,60)))-1,LEN(TRIM(MID(SUBSTITUTE(TRIM(MID($M2,FIND(":",$M2)+1,200)),",",REPT(" ",60)),61,60)))))),2,3)),"") | AE2: =IFERROR(($AC2-$AA2+1)*($AD2-$AB2+1),0) -> 0
F3: =IF(AND($A3<>"",$B3<>"",$C3<>"",$D3<>"",$E3<>""),TODAY(),"") | H3: =IF(AND($A3<>"",$B3<>"",$C3<>"",$D3<>"",$E3<>""),IF(AND($B3="s",OR($C3="SER",$C3="PLH",$C3="CSF")),"Case CDI Plate "&(INT(((COUNTIFS($B$2:$B3,"s",$C$2:$C3,"SER")+COUNTIFS($B$2:$B3,"s",$C$2:$C3,"PLH")+COUNTIFS($B$2:$B3,"s",$C$2:$C3,"CSF"))-1)/96)+1)&": "&CHAR(65+INT(MOD((COUNTIFS($B$2:$B3,"s",$C$2:$C3,"SER")+COUNTIFS($B$2:$B3,"s",$C$2:$C3,"PLH")+COUNTIFS($B$2:$B3,"s",$C$2:$C3,"CSF"))-1,96)/12))&(MOD((COUNTIFS($B$2:$B3,"s",$C$2:$C3,"SER")+COUNTIFS($B$2:$B3,"s",$C$2:$C3,"PLH")+COUNTIFS($B$2:$B3,"s",$C$2:$C3,"CSF"))-1,12)+1),"N/A"),"") | I3: =IF(AND($A3<>"",$B3<>"",$C3<>"",$D3<>"",$E3<>""),IF(AND($B3="s",OR($C3="SER",$C3="PLH",$C3="CSF")),"Case NIH Plate "&(INT(((COUNTIFS($B$2:$B3,"s",$C$2:$C3,"SER")+COUNTIFS($B$2:$B3,"s",$C$2:$C3,"PLH")+COUNTIFS($B$2:$B3,"s",$C$2:$C3,"CSF"))-1)/96)+1)&": "&CHAR(65+INT(MOD((COUNTIFS($B$2:$B3,"s",$C$2:$C3,"SER")+COUNTIFS($B$2:$B3,"s",$C$2:$C3,"PLH")+COUNTIFS($B$2:$B3,"s",$C$2:$C3,"CSF"))-1,96)/12))&(MOD((COUNTIFS($B$2:$B3,"s",$C$2:$C3,"SER")+COUNTIFS($B$2:$B3,"s",$C$2:$C3,"PLH")+COUNTIFS($B$2:$B3,"s",$C$2:$C3,"CSF"))-1,12)+1),"N/A"),"") | J3: =IF(AND($A3<>"",$B3<>"",$C3<>"",$D3<>"",$E3<>""),IF(AND($B3="s",OR($C3="SER",$C3="PLH")),"Case MAX Planck Plate "&(INT(((COUNTIFS($B$2:$B3,"s",$C$2:$C3,"SER")+COUNTIFS($B$2:$B3,"s",$C$2:$C3,"PLH"))-1)/96)+1)&": "&CHAR(65+INT(MOD((COUNTIFS($B$2:$B3,"s",$C$2:$C3,"SER")+COUNTIFS($B$2:$B3,"s",$C$2:$C3,"PLH"))-1,96)/12))&(MOD((COUNTIFS($B$2:$B3,"s",$C$2:$C3,"SER")+COUNTIFS($B$2:$B3,"s",$C$2:$C3,"PLH"))-1,12)+1),"N/A"),"") | K3: =IF(AND($A3<>"",$B3<>"",$C3<>"",$D3<>"",$E3<>""),IF($C3="WB","Case WB Box "&(INT((COUNTIFS($C$2:$C3,"WB")-1)/81)+1)&": "&CHAR(65+INT(MOD(COUNTIFS($C$2:$C3,"WB")-1,81)/9))&(MOD(COUNTIFS($C$2:$C3,"WB")-1,9)+1),"N/A"),"") | L3: =IF(AND($A3<>"",$B3<>"",$C3<>"",$D3<>"",$E3<>""),IF($C3="WB","No",IF($B3="i","Yes","")),"") | P3: =IF($A3<>"",MID($A3,5,4),"") | Q3: =IF($D3<>"",TEXT($D3,"mmddyy"),"") | R3: =IF(AND($A3<>"",$B3<>"",$C3<>"",$D3<>""),IF($C3="WB","cs_"&$P3&"_"&$B3&"_wb_"&$Q3,"cs_"&$P3&"_"&$B3&"_"&LOWER($C3)&"_"&IF($C3="CSF","0.50","0.20")&"_"&$Q3),"") | S3: =IF(AND($A3<>"",$B3<>"",$C3="WB",$D3<>""),"cs_"&$P3&"_"&$B3&"_wb_"&$Q3,"") | T3: =IFERROR(VALUE(MID($M3,FIND("Box ",$M3)+4,FIND(":",$M3)-FIND("Box ",$M3)-4)),"") | U3: =IFERROR(CODE(UPPER(LEFT(LEFT(TRIM(MID(SUBSTITUTE(TRIM(MID($M3,FIND(":",$M3)+1,200)),",",REPT(" ",60)),1,60)),IFERROR(FIND("-",TRIM(MID(SUBSTITUTE(TRIM(MID($M3,FIND(":",$M3)+1,200)),",",REPT(" ",60)),1,60)))-1,LEN(TRIM(MID(SUBSTITUTE(TRIM(MID($M3,FIND(":",$M3)+1,200)),",",REPT(" ",60)),1,60))))),1)))-64,"") | V3: =IFERROR(VALUE(MID(LEFT(TRIM(MID(SUBSTITUTE(TRIM(MID($M3,FIND(":",$M3)+1,200)),",",REPT(" ",60)),1,60)),IFERROR(FIND("-",TRIM(MID(SUBSTITUTE(TRIM(MID($M3,FIND(":",$M3)+1,200)),",",REPT(" ",60)),1,60)))-1,LEN(TRIM(MID(SUBSTITUTE(TRIM(MID($M3,FIND(":",$M3)+1,200)),",",REPT(" ",60)),1,60))))),2,3)),"") | W3: =IFERROR(CODE(UPPER(LEFT(IFERROR(MID(TRIM(MID(SUBSTITUTE(TRIM(MID($M3,FIND(":",$M3)+1,200)),",",REPT(" ",60)),1,60)),FIND("-",TRIM(MID(SUBSTITUTE(TRIM(MID($M3,FIND(":",$M3)+1,200)),",",REPT(" ",60)),1,60)))+1,99),LEFT(TRIM(MID(SUBSTITUTE(TRIM(MID($M3,FIND(":",$M3)+1,200)),",",REPT(" ",60)),1,60)),IFERROR(FIND("-",TRIM(MID(SUBSTITUTE(TRIM(MID($M3,FIND(":",$M3)+1,200)),",",REPT(" ",60)),1,60)))-1,LEN(TRIM(MID(SUBSTITUTE(TRIM(MID($M3,FIND(":",$M3)+1,200)),",",REPT(" ",60)),1,60)))))),1)))-64,"") | X3: =IFERROR(VALUE(MID(IFERROR(MID(TRIM(MID(SUBSTITUTE(TRIM(MID($M3,FIND(":",$M3)+1,200)),",",REPT(" ",60)),1,60)),FIND("-",TRIM(MID(SUBSTITUTE(TRIM(MID($M3,FIND(":",$M3)+1,200)),",",REPT(" ",60)),1,60)))+1,99),LEFT(TRIM(MID(SUBSTITUTE(TRIM(MID($M3,FIND(":",$M3)+1,200)),",",REPT(" ",60)),1,60)),IFERROR(FIND("-",TRIM(MID(SUBSTITUTE(TRIM(MID($M3,FIND(":",$M3)+1,200)),",",REPT(" ",60)),1,60)))-1,LEN(TRIM(MID(SUBSTITUTE(TRIM(MID($M3,FIND(":",$M3)+1,200)),",",REPT(" ",60)),1,60)))))),2,3)),"") | Y3: =IF(AND($A3<>"",$B3<>"",$C3<>"",$D3<>""),"cs_"&$P3&"_"&$B3&"_"&LOWER($C3)&"_","") | Z3: =IFERROR(($W3-$U3+1)*($X3-$V3+1),0) -> 0 | AA3: =IFERROR(CODE(UPPER(LEFT(LEFT(TRIM(MID(SUBSTITUTE(TRIM(MID($M3,FIND(":",$M3)+1,200)),",",REPT(" ",60)),61,60)),IFERROR(FIND("-",TRIM(MID(SUBSTITUTE(TRIM(MID($M3,FIND(":",$M3)+1,200)),",",REPT(" ",60)),61,60)))-1,LEN(TRIM(MID(SUBSTITUTE(TRIM(MID($M3,FIND(":",$M3)+1,200)),",",REPT(" ",60)),61,60))))),1)))-64,"") | AB3: =IFERROR(VALUE(MID(LEFT(TRIM(MID(SUBSTITUTE(TRIM(MID($M3,FIND(":",$M3)+1,200)),",",REPT(" ",60)),61,60)),IFERROR(FIND("-",TRIM(MID(SUBSTITUTE(TRIM(MID($M3,FIND(":",$M3)+1,200)),",",REPT(" ",60)),61,60)))-1,LEN(TRIM(MID(SUBSTITUTE(TRIM(MID($M3,FIND(":",$M3)+1,200)),",",REPT(" ",60)),61,60))))),2,3)),"") | AC3: =IFERROR(CODE(UPPER(LEFT(IFERROR(MID(TRIM(MID(SUBSTITUTE(TRIM(MID($M3,FIND(":",$M3)+1,200)),",",REPT(" ",60)),61,60)),FIND("-",TRIM(MID(SUBSTITUTE(TRIM(MID($M3,FIND(":",$M3)+1,200)),",",REPT(" ",60)),61,60)))+1,99),LEFT(TRIM(MID(SUBSTITUTE(TRIM(MID($M3,FIND(":",$M3)+1,200)),",",REPT(" ",60)),61,60)),IFERROR(FIND("-",TRIM(MID(SUBSTITUTE(TRIM(MID($M3,FIND(":",$M3)+1,200)),",",REPT(" ",60)),61,60)))-1,LEN(TRIM(MID(SUBSTITUTE(TRIM(MID($M3,FIND(":",$M3)+1,200)),",",REPT(" ",60)),61,60)))))),1)))-64,"") | AD3: =IFERROR(VALUE(MID(IFERROR(MID(TRIM(MID(SUBSTITUTE(TRIM(MID($M3,FIND(":",$M3)+1,200)),",",REPT(" ",60)),61,60)),FIND("-",TRIM(MID(SUBSTITUTE(TRIM(MID($M3,FIND(":",$M3)+1,200)),",",REPT(" ",60)),61,60)))+1,99),LEFT(TRIM(MID(SUBSTITUTE(TRIM(MID($M3,FIND(":",$M3)+1,200)),",",REPT(" ",60)),61,60)),IFERROR(FIND("-",TRIM(MID(SUBSTITUTE(TRIM(MID($M3,FIND(":",$M3)+1,200)),",",REPT(" ",60)),61,60)))-1,LEN(TRIM(MID(SUBSTITUTE(TRIM(MID($M3,FIND(":",$M3)+1,200)),",",REPT(" ",60)),61,60)))))),2,3)),"") | AE3: =IFERROR(($AC3-$AA3+1)*($AD3-$AB3+1),0) -> 0
F4: =IF(AND($A4<>"",$B4<>"",$C4<>"",$D4<>"",$E4<>""),TODAY(),"") | H4: =IF(AND($A4<>"",$B4<>"",$C4<>"",$D4<>"",$E4<>""),IF(AND($B4="s",OR($C4="SER",$C4="PLH",$C4="CSF")),"Case CDI Plate "&(INT(((COUNTIFS($B$2:$B4,"s",$C$2:$C4,"SER")+COUNTIFS($B$2:$B4,"s",$C$2:$C4,"PLH")+COUNTIFS($B$2:$B4,"s",$C$2:$C4,"CSF"))-1)/96)+1)&": "&CHAR(65+INT(MOD((COUNTIFS($B$2:$B4,"s",$C$2:$C4,"SER")+COUNTIFS($B$2:$B4,"s",$C$2:$C4,"PLH")+COUNTIFS($B$2:$B4,"s",$C$2:$C4,"CSF"))-1,96)/12))&(MOD((COUNTIFS($B$2:$B4,"s",$C$2:$C4,"SER")+COUNTIFS($B$2:$B4,"s",$C$2:$C4,"PLH")+COUNTIFS($B$2:$B4,"s",$C$2:$C4,"CSF"))-1,12)+1),"N/A"),"") | I4: =IF(AND($A4<>"",$B4<>"",$C4<>"",$D4<>"",$E4<>""),IF(AND($B4="s",OR($C4="SER",$C4="PLH",$C4="CSF")),"Case NIH Plate "&(INT(((COUNTIFS($B$2:$B4,"s",$C$2:$C4,"SER")+COUNTIFS($B$2:$B4,"s",$C$2:$C4,"PLH")+COUNTIFS($B$2:$B4,"s",$C$2:$C4,"CSF"))-1)/96)+1)&": "&CHAR(65+INT(MOD((COUNTIFS($B$2:$B4,"s",$C$2:$C4,"SER")+COUNTIFS($B$2:$B4,"s",$C$2:$C4,"PLH")+COUNTIFS($B$2:$B4,"s",$C$2:$C4,"CSF"))-1,96)/12))&(MOD((COUNTIFS($B$2:$B4,"s",$C$2:$C4,"SER")+COUNTIFS($B$2:$B4,"s",$C$2:$C4,"PLH")+COUNTIFS($B$2:$B4,"s",$C$2:$C4,"CSF"))-1,12)+1),"N/A"),"") | J4: =IF(AND($A4<>"",$B4<>"",$C4<>"",$D4<>"",$E4<>""),IF(AND($B4="s",OR($C4="SER",$C4="PLH")),"Case MAX Planck Plate "&(INT(((COUNTIFS($B$2:$B4,"s",$C$2:$C4,"SER")+COUNTIFS($B$2:$B4,"s",$C$2:$C4,"PLH"))-1)/96)+1)&": "&CHAR(65+INT(MOD((COUNTIFS($B$2:$B4,"s",$C$2:$C4,"SER")+COUNTIFS($B$2:$B4,"s",$C$2:$C4,"PLH"))-1,96)/12))&(MOD((COUNTIFS($B$2:$B4,"s",$C$2:$C4,"SER")+COUNTIFS($B$2:$B4,"s",$C$2:$C4,"PLH"))-1,12)+1),"N/A"),"") | K4: =IF(AND($A4<>"",$B4<>"",$C4<>"",$D4<>"",$E4<>""),IF($C4="WB","Case WB Box "&(INT((COUNTIFS($C$2:$C4,"WB")-1)/81)+1)&": "&CHAR(65+INT(MOD(COUNTIFS($C$2:$C4,"WB")-1,81)/9))&(MOD(COUNTIFS($C$2:$C4,"WB")-1,9)+1),"N/A"),"") | L4: =IF(AND($A4<>"",$B4<>"",$C4<>"",$D4<>"",$E4<>""),IF($C4="WB","No",IF($B4="i","Yes","")),"") | P4: =IF($A4<>"",MID($A4,5,4),"") | Q4: =IF($D4<>"",TEXT($D4,"mmddyy"),"") | R4: =IF(AND($A4<>"",$B4<>"",$C4<>"",$D4<>""),IF($C4="WB","cs_"&$P4&"_"&$B4&"_wb_"&$Q4,"cs_"&$P4&"_"&$B4&"_"&LOWER($C4)&"_"&IF($C4="CSF","0.50","0.20")&"_"&$Q4),"") | S4: =IF(AND($A4<>"",$B4<>"",$C4="WB",$D4<>""),"cs_"&$P4&"_"&$B4&"_wb_"&$Q4,"") | T4: =IFERROR(VALUE(MID($M4,FIND("Box ",$M4)+4,FIND(":",$M4)-FIND("Box ",$M4)-4)),"") | U4: =IFERROR(CODE(UPPER(LEFT(LEFT(TRIM(MID(SUBSTITUTE(TRIM(MID($M4,FIND(":",$M4)+1,200)),",",REPT(" ",60)),1,60)),IFERROR(FIND("-",TRIM(MID(SUBSTITUTE(TRIM(MID($M4,FIND(":",$M4)+1,200)),",",REPT(" ",60)),1,60)))-1,LEN(TRIM(MID(SUBSTITUTE(TRIM(MID($M4,FIND(":",$M4)+1,200)),",",REPT(" ",60)),1,60))))),1)))-64,"") | V4: =IFERROR(VALUE(MID(LEFT(TRIM(MID(SUBSTITUTE(TRIM(MID($M4,FIND(":",$M4)+1,200)),",",REPT(" ",60)),1,60)),IFERROR(FIND("-",TRIM(MID(SUBSTITUTE(TRIM(MID($M4,FIND(":",$M4)+1,200)),",",REPT(" ",60)),1,60)))-1,LEN(TRIM(MID(SUBSTITUTE(TRIM(MID($M4,FIND(":",$M4)+1,200)),",",REPT(" ",60)),1,60))))),2,3)),"") | W4: =IFERROR(CODE(UPPER(LEFT(IFERROR(MID(TRIM(MID(SUBSTITUTE(TRIM(MID($M4,FIND(":",$M4)+1,200)),",",REPT(" ",60)),1,60)),FIND("-",TRIM(MID(SUBSTITUTE(TRIM(MID($M4,FIND(":",$M4)+1,200)),",",REPT(" ",60)),1,60)))+1,99),LEFT(TRIM(MID(SUBSTITUTE(TRIM(MID($M4,FIND(":",$M4)+1,200)),",",REPT(" ",60)),1,60)),IFERROR(FIND("-",TRIM(MID(SUBSTITUTE(TRIM(MID($M4,FIND(":",$M4)+1,200)),",",REPT(" ",60)),1,60)))-1,LEN(TRIM(MID(SUBSTITUTE(TRIM(MID($M4,FIND(":",$M4)+1,200)),",",REPT(" ",60)),1,60)))))),1)))-64,"") | X4: =IFERROR(VALUE(MID(IFERROR(MID(TRIM(MID(SUBSTITUTE(TRIM(MID($M4,FIND(":",$M4)+1,200)),",",REPT(" ",60)),1,60)),FIND("-",TRIM(MID(SUBSTITUTE(TRIM(MID($M4,FIND(":",$M4)+1,200)),",",REPT(" ",60)),1,60)))+1,99),LEFT(TRIM(MID(SUBSTITUTE(TRIM(MID($M4,FIND(":",$M4)+1,200)),",",REPT(" ",60)),1,60)),IFERROR(FIND("-",TRIM(MID(SUBSTITUTE(TRIM(MID($M4,FIND(":",$M4)+1,200)),",",REPT(" ",60)),1,60)))-1,LEN(TRIM(MID(SUBSTITUTE(TRIM(MID($M4,FIND(":",$M4)+1,200)),",",REPT(" ",60)),1,60)))))),2,3)),"") | Y4: =IF(AND($A4<>"",$B4<>"",$C4<>"",$D4<>""),"cs_"&$P4&"_"&$B4&"_"&LOWER($C4)&"_","") | Z4: =IFERROR(($W4-$U4+1)*($X4-$V4+1),0) -> 0 | AA4: =IFERROR(CODE(UPPER(LEFT(LEFT(TRIM(MID(SUBSTITUTE(TRIM(MID($M4,FIND(":",$M4)+1,200)),",",REPT(" ",60)),61,60)),IFERROR(FIND("-",TRIM(MID(SUBSTITUTE(TRIM(MID($M4,FIND(":",$M4)+1,200)),",",REPT(" ",60)),61,60)))-1,LEN(TRIM(MID(SUBSTITUTE(TRIM(MID($M4,FIND(":",$M4)+1,200)),",",REPT(" ",60)),61,60))))),1)))-64,"") | AB4: =IFERROR(VALUE(MID(LEFT(TRIM(MID(SUBSTITUTE(TRIM(MID($M4,FIND(":",$M4)+1,200)),",",REPT(" ",60)),61,60)),IFERROR(FIND("-",TRIM(MID(SUBSTITUTE(TRIM(MID($M4,FIND(":",$M4)+1,200)),",",REPT(" ",60)),61,60)))-1,LEN(TRIM(MID(SUBSTITUTE(TRIM(MID($M4,FIND(":",$M4)+1,200)),",",REPT(" ",60)),61,60))))),2,3)),"") | AC4: =IFERROR(CODE(UPPER(LEFT(IFERROR(MID(TRIM(MID(SUBSTITUTE(TRIM(MID($M4,FIND(":",$M4)+1,200)),",",REPT(" ",60)),61,60)),FIND("-",TRIM(MID(SUBSTITUTE(TRIM(MID($M4,FIND(":",$M4)+1,200)),",",REPT(" ",60)),61,60)))+1,99),LEFT(TRIM(MID(SUBSTITUTE(TRIM(MID($M4,FIND(":",$M4)+1,200)),",",REPT(" ",60)),61,60)),IFERROR(FIND("-",TRIM(MID(SUBSTITUTE(TRIM(MID($M4,FIND(":",$M4)+1,200)),",",REPT(" ",60)),61,60)))-1,LEN(TRIM(MID(SUBSTITUTE(TRIM(MID($M4,FIND(":",$M4)+1,200)),",",REPT(" ",60)),61,60)))))),1)))-64,"") | AD4: =IFERROR(VALUE(MID(IFERROR(MID(TRIM(MID(SUBSTITUTE(TRIM(MID($M4,FIND(":",$M4)+1,200)),",",REPT(" ",60)),61,60)),FIND("-",TRIM(MID(SUBSTITUTE(TRIM(MID($M4,FIND(":",$M4)+1,200)),",",REPT(" ",60)),61,60)))+1,99),LEFT(TRIM(MID(SUBSTITUTE(TRIM(MID($M4,FIND(":",$M4)+1,200)),",",REPT(" ",60)),61,60)),IFERROR(FIND("-",TRIM(MID(SUBSTITUTE(TRIM(MID($M4,FIND(":",$M4)+1,200)),",",REPT(" ",60)),61,60)))-1,LEN(TRIM(MID(SUBSTITUTE(TRIM(MID($M4,FIND(":",$M4)+1,200)),",",REPT(" ",60)),61,60)))))),2,3)),"") | AE4: =IFERROR(($AC4-$AA4+1)*($AD4-$AB4+1),0) -> 0
F5: =IF(AND($A5<>"",$B5<>"",$C5<>"",$D5<>"",$E5<>""),TODAY(),"") | H5: =IF(AND($A5<>"",$B5<>"",$C5<>"",$D5<>"",$E5<>""),IF(AND($B5="s",OR($C5="SER",$C5="PLH",$C5="CSF")),"Case CDI Plate "&(INT(((COUNTIFS($B$2:$B5,"s",$C$2:$C5,"SER")+COUNTIFS($B$2:$B5,"s",$C$2:$C5,"PLH")+COUNTIFS($B$2:$B5,"s",$C$2:$C5,"CSF"))-1)/96)+1)&": "&CHAR(65+INT(MOD((COUNTIFS($B$2:$B5,"s",$C$2:$C5,"SER")+COUNTIFS($B$2:$B5,"s",$C$2:$C5,"PLH")+COUNTIFS($B$2:$B5,"s",$C$2:$C5,"CSF"))-1,96)/12))&(MOD((COUNTIFS($B$2:$B5,"s",$C$2:$C5,"SER")+COUNTIFS($B$2:$B5,"s",$C$2:$C5,"PLH")+COUNTIFS($B$2:$B5,"s",$C$2:$C5,"CSF"))-1,12)+1),"N/A"),"") | I5: =IF(AND($A5<>"",$B5<>"",$C5<>"",$D5<>"",$E5<>""),IF(AND($B5="s",OR($C5="SER",$C5="PLH",$C5="CSF")),"Case NIH Plate "&(INT(((COUNTIFS($B$2:$B5,"s",$C$2:$C5,"SER")+COUNTIFS($B$2:$B5,"s",$C$2:$C5,"PLH")+COUNTIFS($B$2:$B5,"s",$C$2:$C5,"CSF"))-1)/96)+1)&": "&CHAR(65+INT(MOD((COUNTIFS($B$2:$B5,"s",$C$2:$C5,"SER")+COUNTIFS($B$2:$B5,"s",$C$2:$C5,"PLH")+COUNTIFS($B$2:$B5,"s",$C$2:$C5,"CSF"))-1,96)/12))&(MOD((COUNTIFS($B$2:$B5,"s",$C$2:$C5,"SER")+COUNTIFS($B$2:$B5,"s",$C$2:$C5,"PLH")+COUNTIFS($B$2:$B5,"s",$C$2:$C5,"CSF"))-1,12)+1),"N/A"),"") | J5: =IF(AND($A5<>"",$B5<>"",$C5<>"",$D5<>"",$E5<>""),IF(AND($B5="s",OR($C5="SER",$C5="PLH")),"Case MAX Planck Plate "&(INT(((COUNTIFS($B$2:$B5,"s",$C$2:$C5,"SER")+COUNTIFS($B$2:$B5,"s",$C$2:$C5,"PLH"))-1)/96)+1)&": "&CHAR(65+INT(MOD((COUNTIFS($B$2:$B5,"s",$C$2:$C5,"SER")+COUNTIFS($B$2:$B5,"s",$C$2:$C5,"PLH"))-1,96)/12))&(MOD((COUNTIFS($B$2:$B5,"s",$C$2:$C5,"SER")+COUNTIFS($B$2:$B5,"s",$C$2:$C5,"PLH"))-1,12)+1),"N/A"),"") | K5: =IF(AND($A5<>"",$B5<>"",$C5<>"",$D5<>"",$E5<>""),IF($C5="WB","Case WB Box "&(INT((COUNTIFS($C$2:$C5,"WB")-1)/81)+1)&": "&CHAR(65+INT(MOD(COUNTIFS($C$2:$C5,"WB")-1,81)/9))&(MOD(COUNTIFS($C$2:$C5,"WB")-1,9)+1),"N/A"),"") | L5: =IF(AND($A5<>"",$B5<>"",$C5<>"",$D5<>"",$E5<>""),IF($C5="WB","No",IF($B5="i","Yes","")),"") | P5: =IF($A5<>"",MID($A5,5,4),"") | Q5: =IF($D5<>"",TEXT($D5,"mmddyy"),"") | R5: =IF(AND($A5<>"",$B5<>"",$C5<>"",$D5<>""),IF($C5="WB","cs_"&$P5&"_"&$B5&"_wb_"&$Q5,"cs_"&$P5&"_"&$B5&"_"&LOWER($C5)&"_"&IF($C5="CSF","0.50","0.20")&"_"&$Q5),"") | S5: =IF(AND($A5<>"",$B5<>"",$C5="WB",$D5<>""),"cs_"&$P5&"_"&$B5&"_wb_"&$Q5,"") | T5: =IFERROR(VALUE(MID($M5,FIND("Box ",$M5)+4,FIND(":",$M5)-FIND("Box ",$M5)-4)),"") | U5: =IFERROR(CODE(UPPER(LEFT(LEFT(TRIM(MID(SUBSTITUTE(TRIM(MID($M5,FIND(":",$M5)+1,200)),",",REPT(" ",60)),1,60)),IFERROR(FIND("-",TRIM(MID(SUBSTITUTE(TRIM(MID($M5,FIND(":",$M5)+1,200)),",",REPT(" ",60)),1,60)))-1,LEN(TRIM(MID(SUBSTITUTE(TRIM(MID($M5,FIND(":",$M5)+1,200)),",",REPT(" ",60)),1,60))))),1)))-64,"") | V5: =IFERROR(VALUE(MID(LEFT(TRIM(MID(SUBSTITUTE(TRIM(MID($M5,FIND(":",$M5)+1,200)),",",REPT(" ",60)),1,60)),IFERROR(FIND("-",TRIM(MID(SUBSTITUTE(TRIM(MID($M5,FIND(":",$M5)+1,200)),",",REPT(" ",60)),1,60)))-1,LEN(TRIM(MID(SUBSTITUTE(TRIM(MID($M5,FIND(":",$M5)+1,200)),",",REPT(" ",60)),1,60))))),2,3)),"") | W5: =IFERROR(CODE(UPPER(LEFT(IFERROR(MID(TRIM(MID(SUBSTITUTE(TRIM(MID($M5,FIND(":",$M5)+1,200)),",",REPT(" ",60)),1,60)),FIND("-",TRIM(MID(SUBSTITUTE(TRIM(MID($M5,FIND(":",$M5)+1,200)),",",REPT(" ",60)),1,60)))+1,99),LEFT(TRIM(MID(SUBSTITUTE(TRIM(MID($M5,FIND(":",$M5)+1,200)),",",REPT(" ",60)),1,60)),IFERROR(FIND("-",TRIM(MID(SUBSTITUTE(TRIM(MID($M5,FIND(":",$M5)+1,200)),",",REPT(" ",60)),1,60)))-1,LEN(TRIM(MID(SUBSTITUTE(TRIM(MID($M5,FIND(":",$M5)+1,200)),",",REPT(" ",60)),1,60)))))),1)))-64,"") | X5: =IFERROR(VALUE(MID(IFERROR(MID(TRIM(MID(SUBSTITUTE(TRIM(MID($M5,FIND(":",$M5)+1,200)),",",REPT(" ",60)),1,60)),FIND("-",TRIM(MID(SUBSTITUTE(TRIM(MID($M5,FIND(":",$M5)+1,200)),",",REPT(" ",60)),1,60)))+1,99),LEFT(TRIM(MID(SUBSTITUTE(TRIM(MID($M5,FIND(":",$M5)+1,200)),",",REPT(" ",60)),1,60)),IFERROR(FIND("-",TRIM(MID(SUBSTITUTE(TRIM(MID($M5,FIND(":",$M5)+1,200)),",",REPT(" ",60)),1,60)))-1,LEN(TRIM(MID(SUBSTITUTE(TRIM(MID($M5,FIND(":",$M5)+1,200)),",",REPT(" ",60)),1,60)))))),2,3)),"") | Y5: =IF(AND($A5<>"",$B5<>"",$C5<>"",$D5<>""),"cs_"&$P5&"_"&$B5&"_"&LOWER($C5)&"_","") | Z5: =IFERROR(($W5-$U5+1)*($X5-$V5+1),0) -> 0 | AA5: =IFERROR(CODE(UPPER(LEFT(LEFT(TRIM(MID(SUBSTITUTE(TRIM(MID($M5,FIND(":",$M5)+1,200)),",",REPT(" ",60)),61,60)),IFERROR(FIND("-",TRIM(MID(SUBSTITUTE(TRIM(MID($M5,FIND(":",$M5)+1,200)),",",REPT(" ",60)),61,60)))-1,LEN(TRIM(MID(SUBSTITUTE(TRIM(MID($M5,FIND(":",$M5)+1,200)),",",REPT(" ",60)),61,60))))),1)))-64,"") | AB5: =IFERROR(VALUE(MID(LEFT(TRIM(MID(SUBSTITUTE(TRIM(MID($M5,FIND(":",$M5)+1,200)),",",REPT(" ",60)),61,60)),IFERROR(FIND("-",TRIM(MID(SUBSTITUTE(TRIM(MID($M5,FIND(":",$M5)+1,200)),",",REPT(" ",60)),61,60)))-1,LEN(TRIM(MID(SUBSTITUTE(TRIM(MID($M5,FIND(":",$M5)+1,200)),",",REPT(" ",60)),61,60))))),2,3)),"") | AC5: =IFERROR(CODE(UPPER(LEFT(IFERROR(MID(TRIM(MID(SUBSTITUTE(TRIM(MID($M5,FIND(":",$M5)+1,200)),",",REPT(" ",60)),61,60)),FIND("-",TRIM(MID(SUBSTITUTE(TRIM(MID($M5,FIND(":",$M5)+1,200)),",",REPT(" ",60)),61,60)))+1,99),LEFT(TRIM(MID(SUBSTITUTE(TRIM(MID($M5,FIND(":",$M5)+1,200)),",",REPT(" ",60)),61,60)),IFERROR(FIND("-",TRIM(MID(SUBSTITUTE(TRIM(MID($M5,FIND(":",$M5)+1,200)),",",REPT(" ",60)),61,60)))-1,LEN(TRIM(MID(SUBSTITUTE(TRIM(MID($M5,FIND(":",$M5)+1,200)),",",REPT(" ",60)),61,60)))))),1)))-64,"") | AD5: =IFERROR(VALUE(MID(IFERROR(MID(TRIM(MID(SUBSTITUTE(TRIM(MID($M5,FIND(":",$M5)+1,200)),",",REPT(" ",60)),61,60)),FIND("-",TRIM(MID(SUBSTITUTE(TRIM(MID($M5,FIND(":",$M5)+1,200)),",",REPT(" ",60)),61,60)))+1,99),LEFT(TRIM(MID(SUBSTITUTE(TRIM(MID($M5,FIND(":",$M5)+1,200)),",",REPT(" ",60)),61,60)),IFERROR(FIND("-",TRIM(MID(SUBSTITUTE(TRIM(MID($M5,FIND(":",$M5)+1,200)),",",REPT(" ",60)),61,60)))-1,LEN(TRIM(MID(SUBSTITUTE(TRIM(MID($M5,FIND(":",$M5)+1,200)),",",REPT(" ",60)),61,60)))))),2,3)),"") | AE5: =IFERROR(($AC5-$AA5+1)*($AD5-$AB5+1),0) -> 0
F6: =IF(AND($A6<>"",$B6<>"",$C6<>"",$D6<>"",$E6<>""),TODAY(),"") | H6: =IF(AND($A6<>"",$B6<>"",$C6<>"",$D6<>"",$E6<>""),IF(AND($B6="s",OR($C6="SER",$C6="PLH",$C6="CSF")),"Case CDI Plate "&(INT(((COUNTIFS($B$2:$B6,"s",$C$2:$C6,"SER")+COUNTIFS($B$2:$B6,"s",$C$2:$C6,"PLH")+COUNTIFS($B$2:$B6,"s",$C$2:$C6,"CSF"))-1)/96)+1)&": "&CHAR(65+INT(MOD((COUNTIFS($B$2:$B6,"s",$C$2:$C6,"SER")+COUNTIFS($B$2:$B6,"s",$C$2:$C6,"PLH")+COUNTIFS($B$2:$B6,"s",$C$2:$C6,"CSF"))-1,96)/12))&(MOD((COUNTIFS($B$2:$B6,"s",$C$2:$C6,"SER")+COUNTIFS($B$2:$B6,"s",$C$2:$C6,"PLH")+COUNTIFS($B$2:$B6,"s",$C$2:$C6,"CSF"))-1,12)+1),"N/A"),"") | I6: =IF(AND($A6<>"",$B6<>"",$C6<>"",$D6<>"",$E6<>""),IF(AND($B6="s",OR($C6="SER",$C6="PLH",$C6="CSF")),"Case NIH Plate "&(INT(((COUNTIFS($B$2:$B6,"s",$C$2:$C6,"SER")+COUNTIFS($B$2:$B6,"s",$C$2:$C6,"PLH")+COUNTIFS($B$2:$B6,"s",$C$2:$C6,"CSF"))-1)/96)+1)&": "&CHAR(65+INT(MOD((COUNTIFS($B$2:$B6,"s",$C$2:$C6,"SER")+COUNTIFS($B$2:$B6,"s",$C$2:$C6,"PLH")+COUNTIFS($B$2:$B6,"s",$C$2:$C6,"CSF"))-1,96)/12))&(MOD((COUNTIFS($B$2:$B6,"s",$C$2:$C6,"SER")+COUNTIFS($B$2:$B6,"s",$C$2:$C6,"PLH")+COUNTIFS($B$2:$B6,"s",$C$2:$C6,"CSF"))-1,12)+1),"N/A"),"") | J6: =IF(AND($A6<>"",$B6<>"",$C6<>"",$D6<>"",$E6<>""),IF(AND($B6="s",OR($C6="SER",$C6="PLH")),"Case MAX Planck Plate "&(INT(((COUNTIFS($B$2:$B6,"s",$C$2:$C6,"SER")+COUNTIFS($B$2:$B6,"s",$C$2:$C6,"PLH"))-1)/96)+1)&": "&CHAR(65+INT(MOD((COUNTIFS($B$2:$B6,"s",$C$2:$C6,"SER")+COUNTIFS($B$2:$B6,"s",$C$2:$C6,"PLH"))-1,96)/12))&(MOD((COUNTIFS($B$2:$B6,"s",$C$2:$C6,"SER")+COUNTIFS($B$2:$B6,"s",$C$2:$C6,"PLH"))-1,12)+1),"N/A"),"") | K6: =IF(AND($A6<>"",$B6<>"",$C6<>"",$D6<>"",$E6<>""),IF($C6="WB","Case WB Box "&(INT((COUNTIFS($C$2:$C6,"WB")-1)/81)+1)&": "&CHAR(65+INT(MOD(COUNTIFS($C$2:$C6,"WB")-1,81)/9))&(MOD(COUNTIFS($C$2:$C6,"WB")-1,9)+1),"N/A"),"") | L6: =IF(AND($A6<>"",$B6<>"",$C6<>"",$D6<>"",$E6<>""),IF($C6="WB","No",IF($B6="i","Yes","")),"") | P6: =IF($A6<>"",MID($A6,5,4),"") | Q6: =IF($D6<>"",TEXT($D6,"mmddyy"),"") | R6: =IF(AND($A6<>"",$B6<>"",$C6<>"",$D6<>""),IF($C6="WB","cs_"&$P6&"_"&$B6&"_wb_"&$Q6,"cs_"&$P6&"_"&$B6&"_"&LOWER($C6)&"_"&IF($C6="CSF","0.50","0.20")&"_"&$Q6),"") | S6: =IF(AND($A6<>"",$B6<>"",$C6="WB",$D6<>""),"cs_"&$P6&"_"&$B6&"_wb_"&$Q6,"") | T6: =IFERROR(VALUE(MID($M6,FIND("Box ",$M6)+4,FIND(":",$M6)-FIND("Box ",$M6)-4)),"") | U6: =IFERROR(CODE(UPPER(LEFT(LEFT(TRIM(MID(SUBSTITUTE(TRIM(MID($M6,FIND(":",$M6)+1,200)),",",REPT(" ",60)),1,60)),IFERROR(FIND("-",TRIM(MID(SUBSTITUTE(TRIM(MID($M6,FIND(":",$M6)+1,200)),",",REPT(" ",60)),1,60)))-1,LEN(TRIM(MID(SUBSTITUTE(TRIM(MID($M6,FIND(":",$M6)+1,200)),",",REPT(" ",60)),1,60))))),1)))-64,"") | V6: =IFERROR(VALUE(MID(LEFT(TRIM(MID(SUBSTITUTE(TRIM(MID($M6,FIND(":",$M6)+1,200)),",",REPT(" ",60)),1,60)),IFERROR(FIND("-",TRIM(MID(SUBSTITUTE(TRIM(MID($M6,FIND(":",$M6)+1,200)),",",REPT(" ",60)),1,60)))-1,LEN(TRIM(MID(SUBSTITUTE(TRIM(MID($M6,FIND(":",$M6)+1,200)),",",REPT(" ",60)),1,60))))),2,3)),"") | W6: =IFERROR(CODE(UPPER(LEFT(IFERROR(MID(TRIM(MID(SUBSTITUTE(TRIM(MID($M6,FIND(":",$M6)+1,200)),",",REPT(" ",60)),1,60)),FIND("-",TRIM(MID(SUBSTITUTE(TRIM(MID($M6,FIND(":",$M6)+1,200)),",",REPT(" ",60)),1,60)))+1,99),LEFT(TRIM(MID(SUBSTITUTE(TRIM(MID($M6,FIND(":",$M6)+1,200)),",",REPT(" ",60)),1,60)),IFERROR(FIND("-",TRIM(MID(SUBSTITUTE(TRIM(MID($M6,FIND(":",$M6)+1,200)),",",REPT(" ",60)),1,60)))-1,LEN(TRIM(MID(SUBSTITUTE(TRIM(MID($M6,FIND(":",$M6)+1,200)),",",REPT(" ",60)),1,60)))))),1)))-64,"") | X6: =IFERROR(VALUE(MID(IFERROR(MID(TRIM(MID(SUBSTITUTE(TRIM(MID($M6,FIND(":",$M6)+1,200)),",",REPT(" ",60)),1,60)),FIND("-",TRIM(MID(SUBSTITUTE(TRIM(MID($M6,FIND(":",$M6)+1,200)),",",REPT(" ",60)),1,60)))+1,99),LEFT(TRIM(MID(SUBSTITUTE(TRIM(MID($M6,FIND(":",$M6)+1,200)),",",REPT(" ",60)),1,60)),IFERROR(FIND("-",TRIM(MID(SUBSTITUTE(TRIM(MID($M6,FIND(":",$M6)+1,200)),",",REPT(" ",60)),1,60)))-1,LEN(TRIM(MID(SUBSTITUTE(TRIM(MID($M6,FIND(":",$M6)+1,200)),",",REPT(" ",60)),1,60)))))),2,3)),"") | Y6: =IF(AND($A6<>"",$B6<>"",$C6<>"",$D6<>""),"cs_"&$P6&"_"&$B6&"_"&LOWER($C6)&"_","") | Z6: =IFERROR(($W6-$U6+1)*($X6-$V6+1),0) -> 0 | AA6: =IFERROR(CODE(UPPER(LEFT(LEFT(TRIM(MID(SUBSTITUTE(TRIM(MID($M6,FIND(":",$M6)+1,200)),",",REPT(" ",60)),61,60)),IFERROR(FIND("-",TRIM(MID(SUBSTITUTE(TRIM(MID($M6,FIND(":",$M6)+1,200)),",",REPT(" ",60)),61,60)))-1,LEN(TRIM(MID(SUBSTITUTE(TRIM(MID($M6,FIND(":",$M6)+1,200)),",",REPT(" ",60)),61,60))))),1)))-64,"") | AB6: =IFERROR(VALUE(MID(LEFT(TRIM(MID(SUBSTITUTE(TRIM(MID($M6,FIND(":",$M6)+1,200)),",",REPT(" ",60)),61,60)),IFERROR(FIND("-",TRIM(MID(SUBSTITUTE(TRIM(MID($M6,FIND(":",$M6)+1,200)),",",REPT(" ",60)),61,60)))-1,LEN(TRIM(MID(SUBSTITUTE(TRIM(MID($M6,FIND(":",$M6)+1,200)),",",REPT(" ",60)),61,60))))),2,3)),"") | AC6: =IFERROR(CODE(UPPER(LEFT(IFERROR(MID(TRIM(MID(SUBSTITUTE(TRIM(MID($M6,FIND(":",$M6)+1,200)),",",REPT(" ",60)),61,60)),FIND("-",TRIM(MID(SUBSTITUTE(TRIM(MID($M6,FIND(":",$M6)+1,200)),",",REPT(" ",60)),61,60)))+1,99),LEFT(TRIM(MID(SUBSTITUTE(TRIM(MID($M6,FIND(":",$M6)+1,200)),",",REPT(" ",60)),61,60)),IFERROR(FIND("-",TRIM(MID(SUBSTITUTE(TRIM(MID($M6,FIND(":",$M6)+1,200)),",",REPT(" ",60)),61,60)))-1,LEN(TRIM(MID(SUBSTITUTE(TRIM(MID($M6,FIND(":",$M6)+1,200)),",",REPT(" ",60)),61,60)))))),1)))-64,"") | AD6: =IFERROR(VALUE(MID(IFERROR(MID(TRIM(MID(SUBSTITUTE(TRIM(MID($M6,FIND(":",$M6)+1,200)),",",REPT(" ",60)),61,60)),FIND("-",TRIM(MID(SUBSTITUTE(TRIM(MID($M6,FIND(":",$M6)+1,200)),",",REPT(" ",60)),61,60)))+1,99),LEFT(TRIM(MID(SUBSTITUTE(TRIM(MID($M6,FIND(":",$M6)+1,200)),",",REPT(" ",60)),61,60)),IFERROR(FIND("-",TRIM(MID(SUBSTITUTE(TRIM(MID($M6,FIND(":",$M6)+1,200)),",",REPT(" ",60)),61,60)))-1,LEN(TRIM(MID(SUBSTITUTE(TRIM(MID($M6,FIND(":",$M6)+1,200)),",",REPT(" ",60)),61,60)))))),2,3)),"") | AE6: =IFERROR(($AC6-$AA6+1)*($AD6-$AB6+1),0) -> 0
F7: =IF(AND($A7<>"",$B7<>"",$C7<>"",$D7<>"",$E7<>""),TODAY(),"") | H7: =IF(AND($A7<>"",$B7<>"",$C7<>"",$D7<>"",$E7<>""),IF(AND($B7="s",OR($C7="SER",$C7="PLH",$C7="CSF")),"Case CDI Plate "&(INT(((COUNTIFS($B$2:$B7,"s",$C$2:$C7,"SER")+COUNTIFS($B$2:$B7,"s",$C$2:$C7,"PLH")+COUNTIFS($B$2:$B7,"s",$C$2:$C7,"CSF"))-1)/96)+1)&": "&CHAR(65+INT(MOD((COUNTIFS($B$2:$B7,"s",$C$2:$C7,"SER")+COUNTIFS($B$2:$B7,"s",$C$2:$C7,"PLH")+COUNTIFS($B$2:$B7,"s",$C$2:$C7,"CSF"))-1,96)/12))&(MOD((COUNTIFS($B$2:$B7,"s",$C$2:$C7,"SER")+COUNTIFS($B$2:$B7,"s",$C$2:$C7,"PLH")+COUNTIFS($B$2:$B7,"s",$C$2:$C7,"CSF"))-1,12)+1),"N/A"),"") | I7: =IF(AND($A7<>"",$B7<>"",$C7<>"",$D7<>"",$E7<>""),IF(AND($B7="s",OR($C7="SER",$C7="PLH",$C7="CSF")),"Case NIH Plate "&(INT(((COUNTIFS($B$2:$B7,"s",$C$2:$C7,"SER")+COUNTIFS($B$2:$B7,"s",$C$2:$C7,"PLH")+COUNTIFS($B$2:$B7,"s",$C$2:$C7,"CSF"))-1)/96)+1)&": "&CHAR(65+INT(MOD((COUNTIFS($B$2:$B7,"s",$C$2:$C7,"SER")+COUNTIFS($B$2:$B7,"s",$C$2:$C7,"PLH")+COUNTIFS($B$2:$B7,"s",$C$2:$C7,"CSF"))-1,96)/12))&(MOD((COUNTIFS($B$2:$B7,"s",$C$2:$C7,"SER")+COUNTIFS($B$2:$B7,"s",$C$2:$C7,"PLH")+COUNTIFS($B$2:$B7,"s",$C$2:$C7,"CSF"))-1,12)+1),"N/A"),"") | J7: =IF(AND($A7<>"",$B7<>"",$C7<>"",$D7<>"",$E7<>""),IF(AND($B7="s",OR($C7="SER",$C7="PLH")),"Case MAX Planck Plate "&(INT(((COUNTIFS($B$2:$B7,"s",$C$2:$C7,"SER")+COUNTIFS($B$2:$B7,"s",$C$2:$C7,"PLH"))-1)/96)+1)&": "&CHAR(65+INT(MOD((COUNTIFS($B$2:$B7,"s",$C$2:$C7,"SER")+COUNTIFS($B$2:$B7,"s",$C$2:$C7,"PLH"))-1,96)/12))&(MOD((COUNTIFS($B$2:$B7,"s",$C$2:$C7,"SER")+COUNTIFS($B$2:$B7,"s",$C$2:$C7,"PLH"))-1,12)+1),"N/A"),"") | K7: =IF(AND($A7<>"",$B7<>"",$C7<>"",$D7<>"",$E7<>""),IF($C7="WB","Case WB Box "&(INT((COUNTIFS($C$2:$C7,"WB")-1)/81)+1)&": "&CHAR(65+INT(MOD(COUNTIFS($C$2:$C7,"WB")-1,81)/9))&(MOD(COUNTIFS($C$2:$C7,"WB")-1,9)+1),"N/A"),"") | L7: =IF(AND($A7<>"",$B7<>"",$C7<>"",$D7<>"",$E7<>""),IF($C7="WB","No",IF($B7="i","Yes","")),"") | P7: =IF($A7<>"",MID($A7,5,4),"") | Q7: =IF($D7<>"",TEXT($D7,"mmddyy"),"") | R7: =IF(AND($A7<>"",$B7<>"",$C7<>"",$D7<>""),IF($C7="WB","cs_"&$P7&"_"&$B7&"_wb_"&$Q7,"cs_"&$P7&"_"&$B7&"_"&LOWER($C7)&"_"&IF($C7="CSF","0.50","0.20")&"_"&$Q7),"") | S7: =IF(AND($A7<>"",$B7<>"",$C7="WB",$D7<>""),"cs_"&$P7&"_"&$B7&"_wb_"&$Q7,"") | T7: =IFERROR(VALUE(MID($M7,FIND("Box ",$M7)+4,FIND(":",$M7)-FIND("Box ",$M7)-4)),"") | U7: =IFERROR(CODE(UPPER(LEFT(LEFT(TRIM(MID(SUBSTITUTE(TRIM(MID($M7,FIND(":",$M7)+1,200)),",",REPT(" ",60)),1,60)),IFERROR(FIND("-",TRIM(MID(SUBSTITUTE(TRIM(MID($M7,FIND(":",$M7)+1,200)),",",REPT(" ",60)),1,60)))-1,LEN(TRIM(MID(SUBSTITUTE(TRIM(MID($M7,FIND(":",$M7)+1,200)),",",REPT(" ",60)),1,60))))),1)))-64,"") | V7: =IFERROR(VALUE(MID(LEFT(TRIM(MID(SUBSTITUTE(TRIM(MID($M7,FIND(":",$M7)+1,200)),",",REPT(" ",60)),1,60)),IFERROR(FIND("-",TRIM(MID(SUBSTITUTE(TRIM(MID($M7,FIND(":",$M7)+1,200)),",",REPT(" ",60)),1,60)))-1,LEN(TRIM(MID(SUBSTITUTE(TRIM(MID($M7,FIND(":",$M7)+1,200)),",",REPT(" ",60)),1,60))))),2,3)),"") | W7: =IFERROR(CODE(UPPER(LEFT(IFERROR(MID(TRIM(MID(SUBSTITUTE(TRIM(MID($M7,FIND(":",$M7)+1,200)),",",REPT(" ",60)),1,60)),FIND("-",TRIM(MID(SUBSTITUTE(TRIM(MID($M7,FIND(":",$M7)+1,200)),",",REPT(" ",60)),1,60)))+1,99),LEFT(TRIM(MID(SUBSTITUTE(TRIM(MID($M7,FIND(":",$M7)+1,200)),",",REPT(" ",60)),1,60)),IFERROR(FIND("-",TRIM(MID(SUBSTITUTE(TRIM(MID($M7,FIND(":",$M7)+1,200)),",",REPT(" ",60)),1,60)))-1,LEN(TRIM(MID(SUBSTITUTE(TRIM(MID($M7,FIND(":",$M7)+1,200)),",",REPT(" ",60)),1,60)))))),1)))-64,"") | X7: =IFERROR(VALUE(MID(IFERROR(MID(TRIM(MID(SUBSTITUTE(TRIM(MID($M7,FIND(":",$M7)+1,200)),",",REPT(" ",60)),1,60)),FIND("-",TRIM(MID(SUBSTITUTE(TRIM(MID($M7,FIND(":",$M7)+1,200)),",",REPT(" ",60)),1,60)))+1,99),LEFT(TRIM(MID(SUBSTITUTE(TRIM(MID($M7,FIND(":",$M7)+1,200)),",",REPT(" ",60)),1,60)),IFERROR(FIND("-",TRIM(MID(SUBSTITUTE(TRIM(MID($M7,FIND(":",$M7)+1,200)),",",REPT(" ",60)),1,60)))-1,LEN(TRIM(MID(SUBSTITUTE(TRIM(MID($M7,FIND(":",$M7)+1,200)),",",REPT(" ",60)),1,60)))))),2,3)),"") | Y7: =IF(AND($A7<>"",$B7<>"",$C7<>"",$D7<>""),"cs_"&$P7&"_"&$B7&"_"&LOWER($C7)&"_","") | Z7: =IFERROR(($W7-$U7+1)*($X7-$V7+1),0) -> 0 | AA7: =IFERROR(CODE(UPPER(LEFT(LEFT(TRIM(MID(SUBSTITUTE(TRIM(MID($M7,FIND(":",$M7)+1,200)),",",REPT(" ",60)),61,60)),IFERROR(FIND("-",TRIM(MID(SUBSTITUTE(TRIM(MID($M7,FIND(":",$M7)+1,200)),",",REPT(" ",60)),61,60)))-1,LEN(TRIM(MID(SUBSTITUTE(TRIM(MID($M7,FIND(":",$M7)+1,200)),",",REPT(" ",60)),61,60))))),1)))-64,"") | AB7: =IFERROR(VALUE(MID(LEFT(TRIM(MID(SUBSTITUTE(TRIM(MID($M7,FIND(":",$M7)+1,200)),",",REPT(" ",60)),61,60)),IFERROR(FIND("-",TRIM(MID(SUBSTITUTE(TRIM(MID($M7,FIND(":",$M7)+1,200)),",",REPT(" ",60)),61,60)))-1,LEN(TRIM(MID(SUBSTITUTE(TRIM(MID($M7,FIND(":",$M7)+1,200)),",",REPT(" ",60)),61,60))))),2,3)),"") | AC7: =IFERROR(CODE(UPPER(LEFT(IFERROR(MID(TRIM(MID(SUBSTITUTE(TRIM(MID($M7,FIND(":",$M7)+1,200)),",",REPT(" ",60)),61,60)),FIND("-",TRIM(MID(SUBSTITUTE(TRIM(MID($M7,FIND(":",$M7)+1,200)),",",REPT(" ",60)),61,60)))+1,99),LEFT(TRIM(MID(SUBSTITUTE(TRIM(MID($M7,FIND(":",$M7)+1,200)),",",REPT(" ",60)),61,60)),IFERROR(FIND("-",TRIM(MID(SUBSTITUTE(TRIM(MID($M7,FIND(":",$M7)+1,200)),",",REPT(" ",60)),61,60)))-1,LEN(TRIM(MID(SUBSTITUTE(TRIM(MID($M7,FIND(":",$M7)+1,200)),",",REPT(" ",60)),61,60)))))),1)))-64,"") | AD7: =IFERROR(VALUE(MID(IFERROR(MID(TRIM(MID(SUBSTITUTE(TRIM(MID($M7,FIND(":",$M7)+1,200)),",",REPT(" ",60)),61,60)),FIND("-",TRIM(MID(SUBSTITUTE(TRIM(MID($M7,FIND(":",$M7)+1,200)),",",REPT(" ",60)),61,60)))+1,99),LEFT(TRIM(MID(SUBSTITUTE(TRIM(MID($M7,FIND(":",$M7)+1,200)),",",REPT(" ",60)),61,60)),IFERROR(FIND("-",TRIM(MID(SUBSTITUTE(TRIM(MID($M7,FIND(":",$M7)+1,200)),",",REPT(" ",60)),61,60)))-1,LEN(TRIM(MID(SUBSTITUTE(TRIM(MID($M7,FIND(":",$M7)+1,200)),",",REPT(" ",60)),61,60)))))),2,3)),"") | AE7: =IFERROR(($AC7-$AA7+1)*($AD7-$AB7+1),0) -> 0
F8: =IF(AND($A8<>"",$B8<>"",$C8<>"",$D8<>"",$E8<>""),TODAY(),"") | H8: =IF(AND($A8<>"",$B8<>"",$C8<>"",$D8<>"",$E8<>""),IF(AND($B8="s",OR($C8="SER",$C8="PLH",$C8="CSF")),"Case CDI Plate "&(INT(((COUNTIFS($B$2:$B8,"s",$C$2:$C8,"SER")+COUNTIFS($B$2:$B8,"s",$C$2:$C8,"PLH")+COUNTIFS($B$2:$B8,"s",$C$2:$C8,"CSF"))-1)/96)+1)&": "&CHAR(65+INT(MOD((COUNTIFS($B$2:$B8,"s",$C$2:$C8,"SER")+COUNTIFS($B$2:$B8,"s",$C$2:$C8,"PLH")+COUNTIFS($B$2:$B8,"s",$C$2:$C8,"CSF"))-1,96)/12))&(MOD((COUNTIFS($B$2:$B8,"s",$C$2:$C8,"SER")+COUNTIFS($B$2:$B8,"s",$C$2:$C8,"PLH")+COUNTIFS($B$2:$B8,"s",$C$2:$C8,"CSF"))-1,12)+1),"N/A"),"") | I8: =IF(AND($A8<>"",$B8<>"",$C8<>"",$D8<>"",$E8<>""),IF(AND($B8="s",OR($C8="SER",$C8="PLH",$C8="CSF")),"Case NIH Plate "&(INT(((COUNTIFS($B$2:$B8,"s",$C$2:$C8,"SER")+COUNTIFS($B$2:$B8,"s",$C$2:$C8,"PLH")+COUNTIFS($B$2:$B8,"s",$C$2:$C8,"CSF"))-1)/96)+1)&": "&CHAR(65+INT(MOD((COUNTIFS($B$2:$B8,"s",$C$2:$C8,"SER")+COUNTIFS($B$2:$B8,"s",$C$2:$C8,"PLH")+COUNTIFS($B$2:$B8,"s",$C$2:$C8,"CSF"))-1,96)/12))&(MOD((COUNTIFS($B$2:$B8,"s",$C$2:$C8,"SER")+COUNTIFS($B$2:$B8,"s",$C$2:$C8,"PLH")+COUNTIFS($B$2:$B8,"s",$C$2:$C8,"CSF"))-1,12)+1),"N/A"),"") | J8: =IF(AND($A8<>"",$B8<>"",$C8<>"",$D8<>"",$E8<>""),IF(AND($B8="s",OR($C8="SER",$C8="PLH")),"Case MAX Planck Plate "&(INT(((COUNTIFS($B$2:$B8,"s",$C$2:$C8,"SER")+COUNTIFS($B$2:$B8,"s",$C$2:$C8,"PLH"))-1)/96)+1)&": "&CHAR(65+INT(MOD((COUNTIFS($B$2:$B8,"s",$C$2:$C8,"SER")+COUNTIFS($B$2:$B8,"s",$C$2:$C8,"PLH"))-1,96)/12))&(MOD((COUNTIFS($B$2:$B8,"s",$C$2:$C8,"SER")+COUNTIFS($B$2:$B8,"s",$C$2:$C8,"PLH"))-1,12)+1),"N/A"),"") | K8: =IF(AND($A8<>"",$B8<>"",$C8<>"",$D8<>"",$E8<>""),IF($C8="WB","Case WB Box "&(INT((COUNTIFS($C$2:$C8,"WB")-1)/81)+1)&": "&CHAR(65+INT(MOD(COUNTIFS($C$2:$C8,"WB")-1,81)/9))&(MOD(COUNTIFS($C$2:$C8,"WB")-1,9)+1),"N/A"),"") | L8: =IF(AND($A8<>"",$B8<>"",$C8<>"",$D8<>"",$E8<>""),IF($C8="WB","No",IF($B8="i","Yes","")),"") | P8: =IF($A8<>"",MID($A8,5,4),"") | Q8: =IF($D8<>"",TEXT($D8,"mmddyy"),"") | R8: =IF(AND($A8<>"",$B8<>"",$C8<>"",$D8<>""),IF($C8="WB","cs_"&$P8&"_"&$B8&"_wb_"&$Q8,"cs_"&$P8&"_"&$B8&"_"&LOWER($C8)&"_"&IF($C8="CSF","0.50","0.20")&"_"&$Q8),"") | S8: =IF(AND($A8<>"",$B8<>"",$C8="WB",$D8<>""),"cs_"&$P8&"_"&$B8&"_wb_"&$Q8,"") | T8: =IFERROR(VALUE(MID($M8,FIND("Box ",$M8)+4,FIND(":",$M8)-FIND("Box ",$M8)-4)),"") | U8: =IFERROR(CODE(UPPER(LEFT(LEFT(TRIM(MID(SUBSTITUTE(TRIM(MID($M8,FIND(":",$M8)+1,200)),",",REPT(" ",60)),1,60)),IFERROR(FIND("-",TRIM(MID(SUBSTITUTE(TRIM(MID($M8,FIND(":",$M8)+1,200)),",",REPT(" ",60)),1,60)))-1,LEN(TRIM(MID(SUBSTITUTE(TRIM(MID($M8,FIND(":",$M8)+1,200)),",",REPT(" ",60)),1,60))))),1)))-64,"") | V8: =IFERROR(VALUE(MID(LEFT(TRIM(MID(SUBSTITUTE(TRIM(MID($M8,FIND(":",$M8)+1,200)),",",REPT(" ",60)),1,60)),IFERROR(FIND("-",TRIM(MID(SUBSTITUTE(TRIM(MID($M8,FIND(":",$M8)+1,200)),",",REPT(" ",60)),1,60)))-1,LEN(TRIM(MID(SUBSTITUTE(TRIM(MID($M8,FIND(":",$M8)+1,200)),",",REPT(" ",60)),1,60))))),2,3)),"") | W8: =IFERROR(CODE(UPPER(LEFT(IFERROR(MID(TRIM(MID(SUBSTITUTE(TRIM(MID($M8,FIND(":",$M8)+1,200)),",",REPT(" ",60)),1,60)),FIND("-",TRIM(MID(SUBSTITUTE(TRIM(MID($M8,FIND(":",$M8)+1,200)),",",REPT(" ",60)),1,60)))+1,99),LEFT(TRIM(MID(SUBSTITUTE(TRIM(MID($M8,FIND(":",$M8)+1,200)),",",REPT(" ",60)),1,60)),IFERROR(FIND("-",TRIM(MID(SUBSTITUTE(TRIM(MID($M8,FIND(":",$M8)+1,200)),",",REPT(" ",60)),1,60)))-1,LEN(TRIM(MID(SUBSTITUTE(TRIM(MID($M8,FIND(":",$M8)+1,200)),",",REPT(" ",60)),1,60)))))),1)))-64,"") | X8: =IFERROR(VALUE(MID(IFERROR(MID(TRIM(MID(SUBSTITUTE(TRIM(MID($M8,FIND(":",$M8)+1,200)),",",REPT(" ",60)),1,60)),FIND("-",TRIM(MID(SUBSTITUTE(TRIM(MID($M8,FIND(":",$M8)+1,200)),",",REPT(" ",60)),1,60)))+1,99),LEFT(TRIM(MID(SUBSTITUTE(TRIM(MID($M8,FIND(":",$M8)+1,200)),",",REPT(" ",60)),1,60)),IFERROR(FIND("-",TRIM(MID(SUBSTITUTE(TRIM(MID($M8,FIND(":",$M8)+1,200)),",",REPT(" ",60)),1,60)))-1,LEN(TRIM(MID(SUBSTITUTE(TRIM(MID($M8,FIND(":",$M8)+1,200)),",",REPT(" ",60)),1,60)))))),2,3)),"") | Y8: =IF(AND($A8<>"",$B8<>"",$C8<>"",$D8<>""),"cs_"&$P8&"_"&$B8&"_"&LOWER($C8)&"_","") | Z8: =IFERROR(($W8-$U8+1)*($X8-$V8+1),0) -> 0 | AA8: =IFERROR(CODE(UPPER(LEFT(LEFT(TRIM(MID(SUBSTITUTE(TRIM(MID($M8,FIND(":",$M8)+1,200)),",",REPT(" ",60)),61,60)),IFERROR(FIND("-",TRIM(MID(SUBSTITUTE(TRIM(MID($M8,FIND(":",$M8)+1,200)),",",REPT(" ",60)),61,60)))-1,LEN(TRIM(MID(SUBSTITUTE(TRIM(MID($M8,FIND(":",$M8)+1,200)),",",REPT(" ",60)),61,60))))),1)))-64,"") | AB8: =IFERROR(VALUE(MID(LEFT(TRIM(MID(SUBSTITUTE(TRIM(MID($M8,FIND(":",$M8)+1,200)),",",REPT(" ",60)),61,60)),IFERROR(FIND("-",TRIM(MID(SUBSTITUTE(TRIM(MID($M8,FIND(":",$M8)+1,200)),",",REPT(" ",60)),61,60)))-1,LEN(TRIM(MID(SUBSTITUTE(TRIM(MID($M8,FIND(":",$M8)+1,200)),",",REPT(" ",60)),61,60))))),2,3)),"") | AC8: =IFERROR(CODE(UPPER(LEFT(IFERROR(MID(TRIM(MID(SUBSTITUTE(TRIM(MID($M8,FIND(":",$M8)+1,200)),",",REPT(" ",60)),61,60)),FIND("-",TRIM(MID(SUBSTITUTE(TRIM(MID($M8,FIND(":",$M8)+1,200)),",",REPT(" ",60)),61,60)))+1,99),LEFT(TRIM(MID(SUBSTITUTE(TRIM(MID($M8,FIND(":",$M8)+1,200)),",",REPT(" ",60)),61,60)),IFERROR(FIND("-",TRIM(MID(SUBSTITUTE(TRIM(MID($M8,FIND(":",$M8)+1,200)),",",REPT(" ",60)),61,60)))-1,LEN(TRIM(MID(SUBSTITUTE(TRIM(MID($M8,FIND(":",$M8)+1,200)),",",REPT(" ",60)),61,60)))))),1)))-64,"") | AD8: =IFERROR(VALUE(MID(IFERROR(MID(TRIM(MID(SUBSTITUTE(TRIM(MID($M8,FIND(":",$M8)+1,200)),",",REPT(" ",60)),61,60)),FIND("-",TRIM(MID(SUBSTITUTE(TRIM(MID($M8,FIND(":",$M8)+1,200)),",",REPT(" ",60)),61,60)))+1,99),LEFT(TRIM(MID(SUBSTITUTE(TRIM(MID($M8,FIND(":",$M8)+1,200)),",",REPT(" ",60)),61,60)),IFERROR(FIND("-",TRIM(MID(SUBSTITUTE(TRIM(MID($M8,FIND(":",$M8)+1,200)),",",REPT(" ",60)),61,60)))-1,LEN(TRIM(MID(SUBSTITUTE(TRIM(MID($M8,FIND(":",$M8)+1,200)),",",REPT(" ",60)),61,60)))))),2,3)),"") | AE8: =IFERROR(($AC8-$AA8+1)*($AD8-$AB8+1),0) -> 0
F9: =IF(AND($A9<>"",$B9<>"",$C9<>"",$D9<>"",$E9<>""),TODAY(),"") | H9: =IF(AND($A9<>"",$B9<>"",$C9<>"",$D9<>"",$E9<>""),IF(AND($B9="s",OR($C9="SER",$C9="PLH",$C9="CSF")),"Case CDI Plate "&(INT(((COUNTIFS($B$2:$B9,"s",$C$2:$C9,"SER")+COUNTIFS($B$2:$B9,"s",$C$2:$C9,"PLH")+COUNTIFS($B$2:$B9,"s",$C$2:$C9,"CSF"))-1)/96)+1)&": "&CHAR(65+INT(MOD((COUNTIFS($B$2:$B9,"s",$C$2:$C9,"SER")+COUNTIFS($B$2:$B9,"s",$C$2:$C9,"PLH")+COUNTIFS($B$2:$B9,"s",$C$2:$C9,"CSF"))-1,96)/12))&(MOD((COUNTIFS($B$2:$B9,"s",$C$2:$C9,"SER")+COUNTIFS($B$2:$B9,"s",$C$2:$C9,"PLH")+COUNTIFS($B$2:$B9,"s",$C$2:$C9,"CSF"))-1,12)+1),"N/A"),"") | I9: =IF(AND($A9<>"",$B9<>"",$C9<>"",$D9<>"",$E9<>""),IF(AND($B9="s",OR($C9="SER",$C9="PLH",$C9="CSF")),"Case NIH Plate "&(INT(((COUNTIFS($B$2:$B9,"s",$C$2:$C9,"SER")+COUNTIFS($B$2:$B9,"s",$C$2:$C9,"PLH")+COUNTIFS($B$2:$B9,"s",$C$2:$C9,"CSF"))-1)/96)+1)&": "&CHAR(65+INT(MOD((COUNTIFS($B$2:$B9,"s",$C$2:$C9,"SER")+COUNTIFS($B$2:$B9,"s",$C$2:$C9,"PLH")+COUNTIFS($B$2:$B9,"s",$C$2:$C9,"CSF"))-1,96)/12))&(MOD((COUNTIFS($B$2:$B9,"s",$C$2:$C9,"SER")+COUNTIFS($B$2:$B9,"s",$C$2:$C9,"PLH")+COUNTIFS($B$2:$B9,"s",$C$2:$C9,"CSF"))-1,12)+1),"N/A"),"") | J9: =IF(AND($A9<>"",$B9<>"",$C9<>"",$D9<>"",$E9<>""),IF(AND($B9="s",OR($C9="SER",$C9="PLH")),"Case MAX Planck Plate "&(INT(((COUNTIFS($B$2:$B9,"s",$C$2:$C9,"SER")+COUNTIFS($B$2:$B9,"s",$C$2:$C9,"PLH"))-1)/96)+1)&": "&CHAR(65+INT(MOD((COUNTIFS($B$2:$B9,"s",$C$2:$C9,"SER")+COUNTIFS($B$2:$B9,"s",$C$2:$C9,"PLH"))-1,96)/12))&(MOD((COUNTIFS($B$2:$B9,"s",$C$2:$C9,"SER")+COUNTIFS($B$2:$B9,"s",$C$2:$C9,"PLH"))-1,12)+1),"N/A"),"") | K9: =IF(AND($A9<>"",$B9<>"",$C9<>"",$D9<>"",$E9<>""),IF($C9="WB","Case WB Box "&(INT((COUNTIFS($C$2:$C9,"WB")-1)/81)+1)&": "&CHAR(65+INT(MOD(COUNTIFS($C$2:$C9,"WB")-1,81)/9))&(MOD(COUNTIFS($C$2:$C9,"WB")-1,9)+1),"N/A"),"") | L9: =IF(AND($A9<>"",$B9<>"",$C9<>"",$D9<>"",$E9<>""),IF($C9="WB","No",IF($B9="i","Yes","")),"") | P9: =IF($A9<>"",MID($A9,5,4),"") | Q9: =IF($D9<>"",TEXT($D9,"mmddyy"),"") | R9: =IF(AND($A9<>"",$B9<>"",$C9<>"",$D9<>""),IF($C9="WB","cs_"&$P9&"_"&$B9&"_wb_"&$Q9,"cs_"&$P9&"_"&$B9&"_"&LOWER($C9)&"_"&IF($C9="CSF","0.50","0.20")&"_"&$Q9),"") | S9: =IF(AND($A9<>"",$B9<>"",$C9="WB",$D9<>""),"cs_"&$P9&"_"&$B9&"_wb_"&$Q9,"") | T9: =IFERROR(VALUE(MID($M9,FIND("Box ",$M9)+4,FIND(":",$M9)-FIND("Box ",$M9)-4)),"") | U9: =IFERROR(CODE(UPPER(LEFT(LEFT(TRIM(MID(SUBSTITUTE(TRIM(MID($M9,FIND(":",$M9)+1,200)),",",REPT(" ",60)),1,60)),IFERROR(FIND("-",TRIM(MID(SUBSTITUTE(TRIM(MID($M9,FIND(":",$M9)+1,200)),",",REPT(" ",60)),1,60)))-1,LEN(TRIM(MID(SUBSTITUTE(TRIM(MID($M9,FIND(":",$M9)+1,200)),",",REPT(" ",60)),1,60))))),1)))-64,"") | V9: =IFERROR(VALUE(MID(LEFT(TRIM(MID(SUBSTITUTE(TRIM(MID($M9,FIND(":",$M9)+1,200)),",",REPT(" ",60)),1,60)),IFERROR(FIND("-",TRIM(MID(SUBSTITUTE(TRIM(MID($M9,FIND(":",$M9)+1,200)),",",REPT(" ",60)),1,60)))-1,LEN(TRIM(MID(SUBSTITUTE(TRIM(MID($M9,FIND(":",$M9)+1,200)),",",REPT(" ",60)),1,60))))),2,3)),"") | W9: =IFERROR(CODE(UPPER(LEFT(IFERROR(MID(TRIM(MID(SUBSTITUTE(TRIM(MID($M9,FIND(":",$M9)+1,200)),",",REPT(" ",60)),1,60)),FIND("-",TRIM(MID(SUBSTITUTE(TRIM(MID($M9,FIND(":",$M9)+1,200)),",",REPT(" ",60)),1,60)))+1,99),LEFT(TRIM(MID(SUBSTITUTE(TRIM(MID($M9,FIND(":",$M9)+1,200)),",",REPT(" ",60)),1,60)),IFERROR(FIND("-",TRIM(MID(SUBSTITUTE(TRIM(MID($M9,FIND(":",$M9)+1,200)),",",REPT(" ",60)),1,60)))-1,LEN(TRIM(MID(SUBSTITUTE(TRIM(MID($M9,FIND(":",$M9)+1,200)),",",REPT(" ",60)),1,60)))))),1)))-64,"") | X9: =IFERROR(VALUE(MID(IFERROR(MID(TRIM(MID(SUBSTITUTE(TRIM(MID($M9,FIND(":",$M9)+1,200)),",",REPT(" ",60)),1,60)),FIND("-",TRIM(MID(SUBSTITUTE(TRIM(MID($M9,FIND(":",$M9)+1,200)),",",REPT(" ",60)),1,60)))+1,99),LEFT(TRIM(MID(SUBSTITUTE(TRIM(MID($M9,FIND(":",$M9)+1,200)),",",REPT(" ",60)),1,60)),IFERROR(FIND("-",TRIM(MID(SUBSTITUTE(TRIM(MID($M9,FIND(":",$M9)+1,200)),",",REPT(" ",60)),1,60)))-1,LEN(TRIM(MID(SUBSTITUTE(TRIM(MID($M9,FIND(":",$M9)+1,200)),",",REPT(" ",60)),1,60)))))),2,3)),"") | Y9: =IF(AND($A9<>"",$B9<>"",$C9<>"",$D9<>""),"cs_"&$P9&"_"&$B9&"_"&LOWER($C9)&"_","") | Z9: =IFERROR(($W9-$U9+1)*($X9-$V9+1),0) -> 0 | AA9: =IFERROR(CODE(UPPER(LEFT(LEFT(TRIM(MID(SUBSTITUTE(TRIM(MID($M9,FIND(":",$M9)+1,200)),",",REPT(" ",60)),61,60)),IFERROR(FIND("-",TRIM(MID(SUBSTITUTE(TRIM(MID($M9,FIND(":",$M9)+1,200)),",",REPT(" ",60)),61,60)))-1,LEN(TRIM(MID(SUBSTITUTE(TRIM(MID($M9,FIND(":",$M9)+1,200)),",",REPT(" ",60)),61,60))))),1)))-64,"") | AB9: =IFERROR(VALUE(MID(LEFT(TRIM(MID(SUBSTITUTE(TRIM(MID($M9,FIND(":",$M9)+1,200)),",",REPT(" ",60)),61,60)),IFERROR(FIND("-",TRIM(MID(SUBSTITUTE(TRIM(MID($M9,FIND(":",$M9)+1,200)),",",REPT(" ",60)),61,60)))-1,LEN(TRIM(MID(SUBSTITUTE(TRIM(MID($M9,FIND(":",$M9)+1,200)),",",REPT(" ",60)),61,60))))),2,3)),"") | AC9: =IFERROR(CODE(UPPER(LEFT(IFERROR(MID(TRIM(MID(SUBSTITUTE(TRIM(MID($M9,FIND(":",$M9)+1,200)),",",REPT(" ",60)),61,60)),FIND("-",TRIM(MID(SUBSTITUTE(TRIM(MID($M9,FIND(":",$M9)+1,200)),",",REPT(" ",60)),61,60)))+1,99),LEFT(TRIM(MID(SUBSTITUTE(TRIM(MID($M9,FIND(":",$M9)+1,200)),",",REPT(" ",60)),61,60)),IFERROR(FIND("-",TRIM(MID(SUBSTITUTE(TRIM(MID($M9,FIND(":",$M9)+1,200)),",",REPT(" ",60)),61,60)))-1,LEN(TRIM(MID(SUBSTITUTE(TRIM(MID($M9,FIND(":",$M9)+1,200)),",",REPT(" ",60)),61,60)))))),1)))-64,"") | AD9: =IFERROR(VALUE(MID(IFERROR(MID(TRIM(MID(SUBSTITUTE(TRIM(MID($M9,FIND(":",$M9)+1,200)),",",REPT(" ",60)),61,60)),FIND("-",TRIM(MID(SUBSTITUTE(TRIM(MID($M9,FIND(":",$M9)+1,200)),",",REPT(" ",60)),61,60)))+1,99),LEFT(TRIM(MID(SUBSTITUTE(TRIM(MID($M9,FIND(":",$M9)+1,200)),",",REPT(" ",60)),61,60)),IFERROR(FIND("-",TRIM(MID(SUBSTITUTE(TRIM(MID($M9,FIND(":",$M9)+1,200)),",",REPT(" ",60)),61,60)))-1,LEN(TRIM(MID(SUBSTITUTE(TRIM(MID($M9,FIND(":",$M9)+1,200)),",",REPT(" ",60)),61,60)))))),2,3)),"") | AE9: =IFERROR(($AC9-$AA9+1)*($AD9-$AB9+1),0) -> 0
F10: =IF(AND($A10<>"",$B10<>"",$C10<>"",$D10<>"",$E10<>""),TODAY(),"") | H10: =IF(AND($A10<>"",$B10<>"",$C10<>"",$D10<>"",$E10<>""),IF(AND($B10="s",OR($C10="SER",$C10="PLH",$C10="CSF")),"Case CDI Plate "&(INT(((COUNTIFS($B$2:$B10,"s",$C$2:$C10,"SER")+COUNTIFS($B$2:$B10,"s",$C$2:$C10,"PLH")+COUNTIFS($B$2:$B10,"s",$C$2:$C10,"CSF"))-1)/96)+1)&": "&CHAR(65+INT(MOD((COUNTIFS($B$2:$B10,"s",$C$2:$C10,"SER")+COUNTIFS($B$2:$B10,"s",$C$2:$C10,"PLH")+COUNTIFS($B$2:$B10,"s",$C$2:$C10,"CSF"))-1,96)/12))&(MOD((COUNTIFS($B$2:$B10,"s",$C$2:$C10,"SER")+COUNTIFS($B$2:$B10,"s",$C$2:$C10,"PLH")+COUNTIFS($B$2:$B10,"s",$C$2:$C10,"CSF"))-1,12)+1),"N/A"),"") | I10: =IF(AND($A10<>"",$B10<>"",$C10<>"",$D10<>"",$E10<>""),IF(AND($B10="s",OR($C10="SER",$C10="PLH",$C10="CSF")),"Case NIH Plate "&(INT(((COUNTIFS($B$2:$B10,"s",$C$2:$C10,"SER")+COUNTIFS($B$2:$B10,"s",$C$2:$C10,"PLH")+COUNTIFS($B$2:$B10,"s",$C$2:$C10,"CSF"))-1)/96)+1)&": "&CHAR(65+INT(MOD((COUNTIFS($B$2:$B10,"s",$C$2:$C10,"SER")+COUNTIFS($B$2:$B10,"s",$C$2:$C10,"PLH")+COUNTIFS($B$2:$B10,"s",$C$2:$C10,"CSF"))-1,96)/12))&(MOD((COUNTIFS($B$2:$B10,"s",$C$2:$C10,"SER")+COUNTIFS($B$2:$B10,"s",$C$2:$C10,"PLH")+COUNTIFS($B$2:$B10,"s",$C$2:$C10,"CSF"))-1,12)+1),"N/A"),"") | J10: =IF(AND($A10<>"",$B10<>"",$C10<>"",$D10<>"",$E10<>""),IF(AND($B10="s",OR($C10="SER",$C10="PLH")),"Case MAX Planck Plate "&(INT(((COUNTIFS($B$2:$B10,"s",$C$2:$C10,"SER")+COUNTIFS($B$2:$B10,"s",$C$2:$C10,"PLH"))-1)/96)+1)&": "&CHAR(65+INT(MOD((COUNTIFS($B$2:$B10,"s",$C$2:$C10,"SER")+COUNTIFS($B$2:$B10,"s",$C$2:$C10,"PLH"))-1,96)/12))&(MOD((COUNTIFS($B$2:$B10,"s",$C$2:$C10,"SER")+COUNTIFS($B$2:$B10,"s",$C$2:$C10,"PLH"))-1,12)+1),"N/A"),"") | K10: =IF(AND($A10<>"",$B10<>"",$C10<>"",$D10<>"",$E10<>""),IF($C10="WB","Case WB Box "&(INT((COUNTIFS($C$2:$C10,"WB")-1)/81)+1)&": "&CHAR(65+INT(MOD(COUNTIFS($C$2:$C10,"WB")-1,81)/9))&(MOD(COUNTIFS($C$2:$C10,"WB")-1,9)+1),"N/A"),"") | L10: =IF(AND($A10<>"",$B10<>"",$C10<>"",$D10<>"",$E10<>""),IF($C10="WB","No",IF($B10="i","Yes","")),"") | P10: =IF($A10<>"",MID($A10,5,4),"") | Q10: =IF($D10<>"",TEXT($D10,"mmddyy"),"") | R10: =IF(AND($A10<>"",$B10<>"",$C10<>"",$D10<>""),IF($C10="WB","cs_"&$P10&"_"&$B10&"_wb_"&$Q10,"cs_"&$P10&"_"&$B10&"_"&LOWER($C10)&"_"&IF($C10="CSF","0.50","0.20")&"_"&$Q10),"") | S10: =IF(AND($A10<>"",$B10<>"",$C10="WB",$D10<>""),"cs_"&$P10&"_"&$B10&"_wb_"&$Q10,"") | T10: =IFERROR(VALUE(MID($M10,FIND("Box ",$M10)+4,FIND(":",$M10)-FIND("Box ",$M10)-4)),"") | U10: =IFERROR(CODE(UPPER(LEFT(LEFT(TRIM(MID(SUBSTITUTE(TRIM(MID($M10,FIND(":",$M10)+1,200)),",",REPT(" ",60)),1,60)),IFERROR(FIND("-",TRIM(MID(SUBSTITUTE(TRIM(MID($M10,FIND(":",$M10)+1,200)),",",REPT(" ",60)),1,60)))-1,LEN(TRIM(MID(SUBSTITUTE(TRIM(MID($M10,FIND(":",$M10)+1,200)),",",REPT(" ",60)),1,60))))),1)))-64,"") | V10: =IFERROR(VALUE(MID(LEFT(TRIM(MID(SUBSTITUTE(TRIM(MID($M10,FIND(":",$M10)+1,200)),",",REPT(" ",60)),1,60)),IFERROR(FIND("-",TRIM(MID(SUBSTITUTE(TRIM(MID($M10,FIND(":",$M10)+1,200)),",",REPT(" ",60)),1,60)))-1,LEN(TRIM(MID(SUBSTITUTE(TRIM(MID($M10,FIND(":",$M10)+1,200)),",",REPT(" ",60)),1,60))))),2,3)),"") | W10: =IFERROR(CODE(UPPER(LEFT(IFERROR(MID(TRIM(MID(SUBSTITUTE(TRIM(MID($M10,FIND(":",$M10)+1,200)),",",REPT(" ",60)),1,60)),FIND("-",TRIM(MID(SUBSTITUTE(TRIM(MID($M10,FIND(":",$M10)+1,200)),",",REPT(" ",60)),1,60)))+1,99),LEFT(TRIM(MID(SUBSTITUTE(TRIM(MID($M10,FIND(":",$M10)+1,200)),",",REPT(" ",60)),1,60)),IFERROR(FIND("-",TRIM(MID(SUBSTITUTE(TRIM(MID($M10,FIND(":",$M10)+1,200)),",",REPT(" ",60)),1,60)))-1,LEN(TRIM(MID(SUBSTITUTE(TRIM(MID($M10,FIND(":",$M10)+1,200)),",",REPT(" ",60)),1,60)))))),1)))-64,"") | X10: =IFERROR(VALUE(MID(IFERROR(MID(TRIM(MID(SUBSTITUTE(TRIM(MID($M10,FIND(":",$M10)+1,200)),",",REPT(" ",60)),1,60)),FIND("-",TRIM(MID(SUBSTITUTE(TRIM(MID($M10,FIND(":",$M10)+1,200)),",",REPT(" ",60)),1,60)))+1,99),LEFT(TRIM(MID(SUBSTITUTE(TRIM(MID($M10,FIND(":",$M10)+1,200)),",",REPT(" ",60)),1,60)),IFERROR(FIND("-",TRIM(MID(SUBSTITUTE(TRIM(MID($M10,FIND(":",$M10)+1,200)),",",REPT(" ",60)),1,60)))-1,LEN(TRIM(MID(SUBSTITUTE(TRIM(MID($M10,FIND(":",$M10)+1,200)),",",REPT(" ",60)),1,60)))))),2,3)),"") | Y10: =IF(AND($A10<>"",$B10<>"",$C10<>"",$D10<>""),"cs_"&$P10&"_"&$B10&"_"&LOWER($C10)&"_","") | Z10: =IFERROR(($W10-$U10+1)*($X10-$V10+1),0) -> 0 | AA10: =IFERROR(CODE(UPPER(LEFT(LEFT(TRIM(MID(SUBSTITUTE(TRIM(MID($M10,FIND(":",$M10)+1,200)),",",REPT(" ",60)),61,60)),IFERROR(FIND("-",TRIM(MID(SUBSTITUTE(TRIM(MID($M10,FIND(":",$M10)+1,200)),",",REPT(" ",60)),61,60)))-1,LEN(TRIM(MID(SUBSTITUTE(TRIM(MID($M10,FIND(":",$M10)+1,200)),",",REPT(" ",60)),61,60))))),1)))-64,"") | AB10: =IFERROR(VALUE(MID(LEFT(TRIM(MID(SUBSTITUTE(TRIM(MID($M10,FIND(":",$M10)+1,200)),",",REPT(" ",60)),61,60)),IFERROR(FIND("-",TRIM(MID(SUBSTITUTE(TRIM(MID($M10,FIND(":",$M10)+1,200)),",",REPT(" ",60)),61,60)))-1,LEN(TRIM(MID(SUBSTITUTE(TRIM(MID($M10,FIND(":",$M10)+1,200)),",",REPT(" ",60)),61,60))))),2,3)),"") | AC10: =IFERROR(CODE(UPPER(LEFT(IFERROR(MID(TRIM(MID(SUBSTITUTE(TRIM(MID($M10,FIND(":",$M10)+1,200)),",",REPT(" ",60)),61,60)),FIND("-",TRIM(MID(SUBSTITUTE(TRIM(MID($M10,FIND(":",$M10)+1,200)),",",REPT(" ",60)),61,60)))+1,99),LEFT(TRIM(MID(SUBSTITUTE(TRIM(MID($M10,FIND(":",$M10)+1,200)),",",REPT(" ",60)),61,60)),IFERROR(FIND("-",TRIM(MID(SUBSTITUTE(TRIM(MID($M10,FIND(":",$M10)+1,200)),",",REPT(" ",60)),61,60)))-1,LEN(TRIM(MID(SUBSTITUTE(TRIM(MID($M10,FIND(":",$M10)+1,200)),",",REPT(" ",60)),61,60)))))),1)))-64,"") | AD10: =IFERROR(VALUE(MID(IFERROR(MID(TRIM(MID(SUBSTITUTE(TRIM(MID($M10,FIND(":",$M10)+1,200)),",",REPT(" ",60)),61,60)),FIND("-",TRIM(MID(SUBSTITUTE(TRIM(MID($M10,FIND(":",$M10)+1,200)),",",REPT(" ",60)),61,60)))+1,99),LEFT(TRIM(MID(SUBSTITUTE(TRIM(MID($M10,FIND(":",$M10)+1,200)),",",REPT(" ",60)),61,60)),IFERROR(FIND("-",TRIM(MID(SUBSTITUTE(TRIM(MID($M10,FIND(":",$M10)+1,200)),",",REPT(" ",60)),61,60)))-1,LEN(TRIM(MID(SUBSTITUTE(TRIM(MID($M10,FIND(":",$M10)+1,200)),",",REPT(" ",60)),61,60)))))),2,3)),"") | AE10: =IFERROR(($AC10-$AA10+1)*($AD10-$AB10+1),0) -> 0
F11: =IF(AND($A11<>"",$B11<>"",$C11<>"",$D11<>"",$E11<>""),TODAY(),"") | H11: =IF(AND($A11<>"",$B11<>"",$C11<>"",$D11<>"",$E11<>""),IF(AND($B11="s",OR($C11="SER",$C11="PLH",$C11="CSF")),"Case CDI Plate "&(INT(((COUNTIFS($B$2:$B11,"s",$C$2:$C11,"SER")+COUNTIFS($B$2:$B11,"s",$C$2:$C11,"PLH")+COUNTIFS($B$2:$B11,"s",$C$2:$C11,"CSF"))-1)/96)+1)&": "&CHAR(65+INT(MOD((COUNTIFS($B$2:$B11,"s",$C$2:$C11,"SER")+COUNTIFS($B$2:$B11,"s",$C$2:$C11,"PLH")+COUNTIFS($B$2:$B11,"s",$C$2:$C11,"CSF"))-1,96)/12))&(MOD((COUNTIFS($B$2:$B11,"s",$C$2:$C11,"SER")+COUNTIFS($B$2:$B11,"s",$C$2:$C11,"PLH")+COUNTIFS($B$2:$B11,"s",$C$2:$C11,"CSF"))-1,12)+1),"N/A"),"") | I11: =IF(AND($A11<>"",$B11<>"",$C11<>"",$D11<>"",$E11<>""),IF(AND($B11="s",OR($C11="SER",$C11="PLH",$C11="CSF")),"Case NIH Plate "&(INT(((COUNTIFS($B$2:$B11,"s",$C$2:$C11,"SER")+COUNTIFS($B$2:$B11,"s",$C$2:$C11,"PLH")+COUNTIFS($B$2:$B11,"s",$C$2:$C11,"CSF"))-1)/96)+1)&": "&CHAR(65+INT(MOD((COUNTIFS($B$2:$B11,"s",$C$2:$C11,"SER")+COUNTIFS($B$2:$B11,"s",$C$2:$C11,"PLH")+COUNTIFS($B$2:$B11,"s",$C$2:$C11,"CSF"))-1,96)/12))&(MOD((COUNTIFS($B$2:$B11,"s",$C$2:$C11,"SER")+COUNTIFS($B$2:$B11,"s",$C$2:$C11,"PLH")+COUNTIFS($B$2:$B11,"s",$C$2:$C11,"CSF"))-1,12)+1),"N/A"),"") | J11: =IF(AND($A11<>"",$B11<>"",$C11<>"",$D11<>"",$E11<>""),IF(AND($B11="s",OR($C11="SER",$C11="PLH")),"Case MAX Planck Plate "&(INT(((COUNTIFS($B$2:$B11,"s",$C$2:$C11,"SER")+COUNTIFS($B$2:$B11,"s",$C$2:$C11,"PLH"))-1)/96)+1)&": "&CHAR(65+INT(MOD((COUNTIFS($B$2:$B11,"s",$C$2:$C11,"SER")+COUNTIFS($B$2:$B11,"s",$C$2:$C11,"PLH"))-1,96)/12))&(MOD((COUNTIFS($B$2:$B11,"s",$C$2:$C11,"SER")+COUNTIFS($B$2:$B11,"s",$C$2:$C11,"PLH"))-1,12)+1),"N/A"),"") | K11: =IF(AND($A11<>"",$B11<>"",$C11<>"",$D11<>"",$E11<>""),IF($C11="WB","Case WB Box "&(INT((COUNTIFS($C$2:$C11,"WB")-1)/81)+1)&": "&CHAR(65+INT(MOD(COUNTIFS($C$2:$C11,"WB")-1,81)/9))&(MOD(COUNTIFS($C$2:$C11,"WB")-1,9)+1),"N/A"),"") | L11: =IF(AND($A11<>"",$B11<>"",$C11<>"",$D11<>"",$E11<>""),IF($C11="WB","No",IF($B11="i","Yes","")),"") | P11: =IF($A11<>"",MID($A11,5,4),"") | Q11: =IF($D11<>"",TEXT($D11,"mmddyy"),"") | R11: =IF(AND($A11<>"",$B11<>"",$C11<>"",$D11<>""),IF($C11="WB","cs_"&$P11&"_"&$B11&"_wb_"&$Q11,"cs_"&$P11&"_"&$B11&"_"&LOWER($C11)&"_"&IF($C11="CSF","0.50","0.20")&"_"&$Q11),"") | S11: =IF(AND($A11<>"",$B11<>"",$C11="WB",$D11<>""),"cs_"&$P11&"_"&$B11&"_wb_"&$Q11,"") | T11: =IFERROR(VALUE(MID($M11,FIND("Box ",$M11)+4,FIND(":",$M11)-FIND("Box ",$M11)-4)),"") | U11: =IFERROR(CODE(UPPER(LEFT(LEFT(TRIM(MID(SUBSTITUTE(TRIM(MID($M11,FIND(":",$M11)+1,200)),",",REPT(" ",60)),1,60)),IFERROR(FIND("-",TRIM(MID(SUBSTITUTE(TRIM(MID($M11,FIND(":",$M11)+1,200)),",",REPT(" ",60)),1,60)))-1,LEN(TRIM(MID(SUBSTITUTE(TRIM(MID($M11,FIND(":",$M11)+1,200)),",",REPT(" ",60)),1,60))))),1)))-64,"") | V11: =IFERROR(VALUE(MID(LEFT(TRIM(MID(SUBSTITUTE(TRIM(MID($M11,FIND(":",$M11)+1,200)),",",REPT(" ",60)),1,60)),IFERROR(FIND("-",TRIM(MID(SUBSTITUTE(TRIM(MID($M11,FIND(":",$M11)+1,200)),",",REPT(" ",60)),1,60)))-1,LEN(TRIM(MID(SUBSTITUTE(TRIM(MID($M11,FIND(":",$M11)+1,200)),",",REPT(" ",60)),1,60))))),2,3)),"") | W11: =IFERROR(CODE(UPPER(LEFT(IFERROR(MID(TRIM(MID(SUBSTITUTE(TRIM(MID($M11,FIND(":",$M11)+1,200)),",",REPT(" ",60)),1,60)),FIND("-",TRIM(MID(SUBSTITUTE(TRIM(MID($M11,FIND(":",$M11)+1,200)),",",REPT(" ",60)),1,60)))+1,99),LEFT(TRIM(MID(SUBSTITUTE(TRIM(MID($M11,FIND(":",$M11)+1,200)),",",REPT(" ",60)),1,60)),IFERROR(FIND("-",TRIM(MID(SUBSTITUTE(TRIM(MID($M11,FIND(":",$M11)+1,200)),",",REPT(" ",60)),1,60)))-1,LEN(TRIM(MID(SUBSTITUTE(TRIM(MID($M11,FIND(":",$M11)+1,200)),",",REPT(" ",60)),1,60)))))),1)))-64,"") | X11: =IFERROR(VALUE(MID(IFERROR(MID(TRIM(MID(SUBSTITUTE(TRIM(MID($M11,FIND(":",$M11)+1,200)),",",REPT(" ",60)),1,60)),FIND("-",TRIM(MID(SUBSTITUTE(TRIM(MID($M11,FIND(":",$M11)+1,200)),",",REPT(" ",60)),1,60)))+1,99),LEFT(TRIM(MID(SUBSTITUTE(TRIM(MID($M11,FIND(":",$M11)+1,200)),",",REPT(" ",60)),1,60)),IFERROR(FIND("-",TRIM(MID(SUBSTITUTE(TRIM(MID($M11,FIND(":",$M11)+1,200)),",",REPT(" ",60)),1,60)))-1,LEN(TRIM(MID(SUBSTITUTE(TRIM(MID($M11,FIND(":",$M11)+1,200)),",",REPT(" ",60)),1,60)))))),2,3)),"") | Y11: =IF(AND($A11<>"",$B11<>"",$C11<>"",$D11<>""),"cs_"&$P11&"_"&$B11&"_"&LOWER($C11)&"_","") | Z11: =IFERROR(($W11-$U11+1)*($X11-$V11+1),0) -> 0 | AA11: =IFERROR(CODE(UPPER(LEFT(LEFT(TRIM(MID(SUBSTITUTE(TRIM(MID($M11,FIND(":",$M11)+1,200)),",",REPT(" ",60)),61,60)),IFERROR(FIND("-",TRIM(MID(SUBSTITUTE(TRIM(MID($M11,FIND(":",$M11)+1,200)),",",REPT(" ",60)),61,60)))-1,LEN(TRIM(MID(SUBSTITUTE(TRIM(MID($M11,FIND(":",$M11)+1,200)),",",REPT(" ",60)),61,60))))),1)))-64,"") | AB11: =IFERROR(VALUE(MID(LEFT(TRIM(MID(SUBSTITUTE(TRIM(MID($M11,FIND(":",$M11)+1,200)),",",REPT(" ",60)),61,60)),IFERROR(FIND("-",TRIM(MID(SUBSTITUTE(TRIM(MID($M11,FIND(":",$M11)+1,200)),",",REPT(" ",60)),61,60)))-1,LEN(TRIM(MID(SUBSTITUTE(TRIM(MID($M11,FIND(":",$M11)+1,200)),",",REPT(" ",60)),61,60))))),2,3)),"") | AC11: =IFERROR(CODE(UPPER(LEFT(IFERROR(MID(TRIM(MID(SUBSTITUTE(TRIM(MID($M11,FIND(":",$M11)+1,200)),",",REPT(" ",60)),61,60)),FIND("-",TRIM(MID(SUBSTITUTE(TRIM(MID($M11,FIND(":",$M11)+1,200)),",",REPT(" ",60)),61,60)))+1,99),LEFT(TRIM(MID(SUBSTITUTE(TRIM(MID($M11,FIND(":",$M11)+1,200)),",",REPT(" ",60)),61,60)),IFERROR(FIND("-",TRIM(MID(SUBSTITUTE(TRIM(MID($M11,FIND(":",$M11)+1,200)),",",REPT(" ",60)),61,60)))-1,LEN(TRIM(MID(SUBSTITUTE(TRIM(MID($M11,FIND(":",$M11)+1,200)),",",REPT(" ",60)),61,60)))))),1)))-64,"") | AD11: =IFERROR(VALUE(MID(IFERROR(MID(TRIM(MID(SUBSTITUTE(TRIM(MID($M11,FIND(":",$M11)+1,200)),",",REPT(" ",60)),61,60)),FIND("-",TRIM(MID(SUBSTITUTE(TRIM(MID($M11,FIND(":",$M11)+1,200)),",",REPT(" ",60)),61,60)))+1,99),LEFT(TRIM(MID(SUBSTITUTE(TRIM(MID($M11,FIND(":",$M11)+1,200)),",",REPT(" ",60)),61,60)),IFERROR(FIND("-",TRIM(MID(SUBSTITUTE(TRIM(MID($M11,FIND(":",$M11)+1,200)),",",REPT(" ",60)),61,60)))-1,LEN(TRIM(MID(SUBSTITUTE(TRIM(MID($M11,FIND(":",$M11)+1,200)),",",REPT(" ",60)),61,60)))))),2,3)),"") | AE11: =IFERROR(($AC11-$AA11+1)*($AD11-$AB11+1),0) -> 0
